Workbook

Sheet Resumo
A1: Médias Diárias
A2: Mês | B2: Created | C2: Resolved | D2: Fernando | E2: Everton | F2: Raphael | G2: Andre | H2: Não atribuídos | I2: Camille | J2: Jean
A3: Janeiro | B3: ='Jan-23'!B24 -> 9.2272727 | C3: ='Jan-23'!C24 -> 8.5454545 | D3: ='Jan-23'!D24 -> 0.86363636 | E3: ='Jan-23'!E24 -> 0.5 | F3: ='Jan-23'!F24 -> 1.5454545 | G3: ='Jan-23'!G24 -> 5.2727273 | H3: ='Jan-23'!H24 -> 0 | I3: ='Jan-23'!I24 -> 0.36363636
A4: Fevereiro | B4: ='Fev-23'!B20 -> 10.666667 | C4: ='Fev-23'!C20 -> 10.611111 | D4: ='Fev-23'!D20 -> 0.94444444 | E4: ='Fev-23'!E20 -> 1.7222222 | F4: ='Fev-23'!F20 -> 2.3333333 | G4: ='Fev-23'!G20 -> 5.3333333 | H4: ='Fev-23'!H20 -> 0 | I4: ='Fev-23'!I20 -> 0.27777778
A5: Março | B5: ='Mar-23'!B26 -> 11.958333 | C5: ='Mar-23'!C26 -> 12.166667 | D5: ='Mar-23'!D26 -> 1.0833333 | E5: ='Mar-23'!E26 -> 1.8333333 | F5: ='Mar-23'!F26 -> 2.3333333 | G5: ='Mar-23'!G26 -> 5.7916667 | H5: ='Mar-23'!H26 -> 0 | I5: ='Mar-23'!I26 -> 1.125
A6: Abril | B6: ='Abr-23'!B21 -> 11 | C6: ='Abr-23'!C21 -> 11.157895 | D6: ='Abr-23'!D21 -> 0.73684211 | E6: ='Abr-23'!E21 -> 2.2105263 | F6: ='Abr-23'!F21 -> 1.3684211 | G6: ='Abr-23'!G21 -> 5.3684211 | H6: ='Abr-23'!H21 -> 0 | I6: ='Abr-23'!I21 -> 1.4736842
A7: Maio | B7: ='Mai-23'!B24 -> 11.818182 | C7: ='Mai-23'!C24 -> 12.136364 | D7: ='Mai-23'!D24 -> 0.36363636 | E7: ='Mai-23'!E24 -> 1.7272727 | F7: ='Mai-23'!F24 -> 2.0454545 | G7: ='Mai-23'!G24 -> 5.4090909 | H7: ='Mai-23'!H24 -> 0 | I7: ='Mai-23'!I24 -> 2.5909091
A8: Junho | B8: ='Jun-23'!B24 -> 12.590909 | C8: ='Jun-23'!C24 -> 12.045455 | D8: ='Jun-23'!D24 -> 1 | E8: ='Jun-23'!E24 -> 2.1363636 | F8: ='Jun-23'!F24 -> 1.9545455 | G8: ='Jun-23'!G24 -> 5.1818182 | H8: ='Jun-23'!H24 -> 0 | I8: ='Jun-23'!I24 -> 1.7727273
A9: Julho | B9: ='Jul-23'!B23 -> 8.6666667 | C9: ='Jul-23'!C23 -> 8.6190476 | D9: ='Jul-23'!D23 -> 0.38095238 | E9: ='Jul-23'!E23 -> 1.1428571 | F9: ='Jul-23'!F23 -> 2 | G9: ='Jul-23'!G23 -> 4.0952381 | H9: ='Jul-23'!H23 -> 0 | I9: ='Jul-23'!I23 -> 1
A10: Agosto | B10: ='Ago-23'!B25 -> 10.086957 | C10: ='Ago-23'!C25 -> 9.3913043 | D10: ='Ago-23'!D25 -> 0.47826087 | E10: ='Ago-23'!E25 -> 1.7826087 | F10: ='Ago-23'!F25 -> 2.3913043 | G10: ='Ago-23'!G25 -> 2.3913043 | H10: ='Ago-23'!H25 -> 0 | I10: ='Ago-23'!I25 -> 2.3478261
A11: Setembro | B11: ='Set-23'!B22 -> 9.25 | C11: ='Set-23'!C22 -> 9.05 | D11: ='Set-23'!D22 -> 0.75 | E11: ='Set-23'!E22 -> 1 | F11: ='Set-23'!F22 -> 2.25 | G11: ='Set-23'!G22 -> 3.55 | H11: ='Set-23'!H22 -> 0 | I11: ='Set-23'!I22 -> 1.45 | J11: ='Set-23'!J22 -> 0.05
A12: Outubro | B12: ='Out-23'!B24 -> 7.5454545 | C12: ='Out-23'!C24 -> 7.6818182 | D12: ='Out-23'!D24 -> 0 | E12: ='Out-23'!E24 -> 0.86363636 | F12: ='Out-23'!F24 -> 2.7272727 | G12: ='Out-23'!G24 -> 1.25 | H12: ='Out-23'!H24 -> 0 | I12: ='Out-23'!I24 -> 1.4545455 | J12: ='Out-23'!J24 -> 1.9545455
A13: Novembro | B13: ='Nov-23'!B21 -> 9 | C13: ='Nov-23'!C21 -> 8.4210526 | D13: 0 | E13: ='Nov-23'!D21 -> 1 | F13: ='Nov-23'!E21 -> 1.8947368 | G13: ='Nov-23'!F21 -> 2.5263158 | H13: ='Nov-23'!G21 -> 0 | I13: ='Nov-23'!H21 -> 1.0526316 | J13: ='Nov-23'!I21 -> 1.9473684
A14: Dezembro | B14: ='Dez-23'!B22 -> 10.3 | C14: ='Dez-23'!C22 -> 9.55 | D14: 0 | E14: ='Dez-23'!D22 -> 1.1 | F14: ='Dez-23'!E22 -> 1.5 | G14: ='Dez-23'!F22 -> 2.85 | H14: 0 | I14: ='Dez-23'!H22 -> 1.9 | J14: ='Dez-23'!I22 -> 2.2
A15: MÉDIA DIÁRIA | B15: =AVERAGE(B3:B14) -> 10.17587 | C15: =AVERAGE(C3:C14) -> 9.948014 | D15: =AVERAGE(D3:D14) -> 0.55009216 | E15: =AVERAGE(E3:E14) -> 1.418235 | F15: =AVERAGE(F3:F14) -> 2.0286547 | G15: =AVERAGE(G3:G14) -> 4.084993 | H15: =AVERAGE(H3:H14) -> 0 | I15: =AVERAGE(I3:I14) -> 1.4007282 | J15: =AVERAGE(J11:J14) -> 1.5379785
A18: Somatórias
A19: Mês | B19: Created | C19: Resolved | D19: Fernando | E19: Everton | F19: Raphael | G19: Andre | H19: Não atribuídos | I19: Camille | J19: Jean
A20: Janeiro | B20: ='Jan-23'!B25 -> 203 | C20: ='Jan-23'!C25 -> 188 | D20: ='Jan-23'!D25 -> 19 | E20: ='Jan-23'!E25 -> 11 | F20: ='Jan-23'!F25 -> 34 | G20: ='Jan-23'!G25 -> 116 | H20: ='Jan-23'!H25 -> 0 | I20: ='Jan-23'!I25 -> 8
A21: Fevereiro | B21: ='Fev-23'!B21 -> 192 | C21: ='Fev-23'!C21 -> 191 | D21: ='Fev-23'!D21 -> 17 | E21: ='Fev-23'!E21 -> 31 | F21: ='Fev-23'!F21 -> 42 | G21: ='Fev-23'!G21 -> 96 | H21: ='Fev-23'!H21 -> 0 | I21: ='Fev-23'!I21 -> 5
A22: Março | B22: ='Mar-23'!B27 -> 287 | C22: ='Mar-23'!C27 -> 292 | D22: ='Mar-23'!D27 -> 26 | E22: ='Mar-23'!E27 -> 44 | F22: ='Mar-23'!F27 -> 56 | G22: ='Mar-23'!G27 -> 139 | H22: ='Mar-23'!H27 -> 0 | I22: ='Mar-23'!I27 -> 27
A23: Abril | B23: ='Abr-23'!B22 -> 209 | C23: ='Abr-23'!C22 -> 212 | D23: ='Abr-23'!D22 -> 14 | E23: ='Abr-23'!E22 -> 42 | F23: ='Abr-23'!F22 -> 26 | G23: ='Abr-23'!G22 -> 102 | H23: ='Abr-23'!H22 -> 0 | I23: ='Abr-23'!I22 -> 28
A24: Maio | B24: ='Mai-23'!B25 -> 260 | C24: ='Mai-23'!C25 -> 267 | D24: ='Mai-23'!D25 -> 8 | E24: ='Mai-23'!E25 -> 38 | F24: ='Mai-23'!F25 -> 45 | G24: ='Mai-23'!G25 -> 119 | H24: ='Mai-23'!H25 -> 0 | I24: ='Mai-23'!I25 -> 57
A25: Junho | B25: ='Jun-23'!B25 -> 277 | C25: ='Jun-23'!C25 -> 265 | D25: ='Jun-23'!D25 -> 22 | E25: ='Jun-23'!E25 -> 47 | F25: ='Jun-23'!F25 -> 43 | G25: ='Jun-23'!G25 -> 114 | H25: ='Jun-23'!H25 -> 0 | I25: ='Jun-23'!I25 -> 39
A26: Julho | B26: ='Jul-23'!B24 -> 182 | C26: ='Jul-23'!C24 -> 181 | D26: ='Jul-23'!D24 -> 8 | E26: ='Jul-23'!E24 -> 24 | F26: ='Jul-23'!F24 -> 42 | G26: ='Jul-23'!G24 -> 86 | H26: ='Jul-23'!H24 -> 0 | I26: ='Jul-23'!I24 -> 21
A27: Agosto | B27: ='Ago-23'!B26 -> 232 | C27: ='Ago-23'!C26 -> 216 | D27: ='Ago-23'!D26 -> 11 | E27: ='Ago-23'!E26 -> 41 | F27: ='Ago-23'!F26 -> 55 | G27: ='Ago-23'!G26 -> 55 | H27: ='Ago-23'!H26 -> 0 | I27: ='Ago-23'!I26 -> 54
A28: Setembro | B28: ='Set-23'!B23 -> 185 | C28: ='Set-23'!C23 -> 181 | D28: ='Set-23'!D23 -> 15 | E28: ='Set-23'!E23 -> 20 | F28: ='Set-23'!F23 -> 45 | G28: ='Set-23'!G23 -> 71 | H28: ='Set-23'!H23 -> 0 | I28: ='Set-23'!I23 -> 29 | J28: ='Set-23'!J23 -> 1
A29: Outubro | B29: ='Out-23'!B25 -> 166 | C29: ='Out-23'!C25 -> 169 | D29: ='Out-23'!D25 -> 0 | E29: ='Out-23'!E25 -> 19 | F29: ='Out-23'!F25 -> 60 | G29: ='Out-23'!G25 -> 15 | H29: ='Out-23'!H25 -> 0 | I29: ='Out-23'!I25 -> 32 | J29: ='Out-23'!J25 -> 43
A30: Novembro | B30: ='Nov-23'!B22 -> 171 | C30: ='Nov-23'!C22 -> 160 | D30: 0 | E30: ='Nov-23'!D22 -> 19 | F30: ='Nov-23'!E22 -> 36 | G30: ='Nov-23'!F22 -> 48 | H30: ='Nov-23'!G22 -> 0 | I30: ='Nov-23'!H22 -> 20 | J30: ='Nov-23'!I22 -> 37
A31: Dezembro | B31: ='Dez-23'!B23 -> 206 | C31: ='Dez-23'!C23 -> 191 | D31: 0 | E31: ='Dez-23'!D23 -> 22 | F31: ='Dez-23'!E23 -> 30 | G31: ='Dez-23'!F23 -> 57 | H31: 0 | I31: ='Dez-23'!H23 -> 38 | J31: ='Dez-23'!I23 -> 44
A32: TOTAL NO ANO | B32: =SUM(B20:B31) -> 2570 | C32: =SUM(C20:C31) -> 2513 | D32: =SUM(D20:D31) -> 140 | E32: =SUM(E20:E31) -> 358 | F32: =SUM(F20:F31) -> 514 | G32: =SUM(G20:G31) -> 1018 | H32: =SUM(H20:H31) -> 0 | I32: =SUM(I20:I31) -> 358 | J32: =SUM(J20:J31) -> 125
A33: MÉDIA MENSAL | B33: =AVERAGE(B20:B31) -> 214.16667 | C33: =AVERAGE(C20:C31) -> 209.41667 | D33: =AVERAGE(D20:D31) -> 11.666667 | E33: =AVERAGE(E20:E31) -> 29.833333 | F33: =AVERAGE(F20:F31) -> 42.833333 | G33: =AVERAGE(G20:G31) -> 84.833333 | H33: =AVERAGE(H20:H31) -> 0 | I33: =AVERAGE(I20:I31) -> 29.833333 | J33: =AVERAGE(J20:J31) -> 31.25
A36: Porcentagem
A37: Mês | B37: Fernando | C37: Everton | D37: Raphael | E37: Andre | F37: Não atribuídos | G37: Camille | H37: Jean | I37: TOTAL
A38: Janeiro | B38: ='Jan-23'!D26 -> 10.106383 | C38: ='Jan-23'!E26 -> 5.8510638 | D38: ='Jan-23'!F26 -> 18.085106 | E38: ='Jan-23'!G26 -> 61.702128 | F38: ='Jan-23'!H26 -> 0 | G38: ='Jan-23'!I26 -> 4.2553191 | I38: =SUM(B38:G38) -> 100
A39: Fevereiro | B39: ='Fev-23'!D22 -> 8.9005236 | C39: ='Fev-23'!E22 -> 16.230366 | D39: ='Fev-23'!F22 -> 21.989529 | E39: ='Fev-23'!G22 -> 50.26178 | F39: ='Fev-23'!H22 -> 0 | G39: ='Fev-23'!I22 -> 2.617801 | I39: =SUM(B39:G39) -> 100
A40: Março | B40: ='Mar-23'!D28 -> 8.9041096 | C40: ='Mar-23'!E28 -> 15.068493 | D40: ='Mar-23'!F28 -> 19.178082 | E40: ='Mar-23'!G28 -> 47.60274 | F40: ='Mar-23'!H28 -> 0 | G40: ='Mar-23'!I28 -> 9.2465753 | I40: =SUM(B40:G40) -> 100
A41: Abril | B41: ='Abr-23'!D23 -> 6.6037736 | C41: ='Abr-23'!E23 -> 19.811321 | D41: ='Abr-23'!F23 -> 12.264151 | E41: ='Abr-23'!G23 -> 48.113208 | F41: ='Abr-23'!H23 -> 0 | G41: ='Abr-23'!I23 -> 13.207547 | I41: =SUM(B41:G41) -> 100
A42: Maio | B42: ='Mai-23'!D26 -> 2.9962547 | C42: ='Mai-23'!E26 -> 14.23221 | D42: ='Mai-23'!F26 -> 16.853933 | E42: ='Mai-23'!G26 -> 44.569288 | F42: ='Mai-23'!H26 -> 0 | G42: ='Mai-23'!I26 -> 21.348315 | I42: =SUM(B42:G42) -> 100
A43: Junho | B43: ='Jun-23'!D26 -> 8.3018868 | C43: ='Jun-23'!E26 -> 17.735849 | D43: ='Jun-23'!F26 -> 16.226415 | E43: ='Jun-23'!G26 -> 43.018868 | F43: ='Jun-23'!H26 -> 0 | G43: ='Jun-23'!I26 -> 14.716981 | I43: =SUM(B43:G43) -> 100
A44: Julho | B44: ='Jul-23'!D25 -> 4.4198895 | C44: ='Jul-23'!E25 -> 13.259669 | D44: ='Jul-23'!F25 -> 23.20442 | E44: ='Jul-23'!G25 -> 47.513812 | F44: ='Jul-23'!H25 -> 0 | G44: ='Jul-23'!I25 -> 11.60221 | I44: =SUM(B44:G44) -> 100
...

Sheet Jan-23
A1: Data | B1: Created | C1: Resolved | D1: Fernando | E1: Everton | F1: Rapahel | G1: Andre | H1: Não atribuídos | I1: Camille
A2: segunda-feira, 2 de janeiro de 2023 | B2: 7 | C2: 3 | D2: 0 | E2: 0 | F2: 0 | G2: 3 | H2: 0 | I2: 0
A3: terça-feira, 3 de janeiro de 2023 | B3: 11 | C3: 9 | D3: 1 | E3: 1 | F3: 0 | G3: 7 | H3: 0 | I3: 0
A4: quarta-feira, 4 de janeiro de 2023 | B4: 12 | C4: 13 | D4: 3 | E4: 5 | F4: 0 | G4: 5 | H4: 0 | I4: 0
A5: quinta-feira, 5 de janeiro de 2023 | B5: 19 | C5: 5 | D5: 0 | E5: 0 | F5: 0 | G5: 5 | H5: 0 | I5: 0
A6: sexta-feira, 6 de janeiro de 2023 | B6: 7 | C6: 8 | D6: 3 | E6: 0 | F6: 0 | G6: 5 | H6: 0 | I6: 0
A7: segunda-feira, 9 de janeiro de 2023 | B7: 10 | C7: 13 | D7: 1 | E7: 1 | F7: 1 | G7: 10 | H7: 0 | I7: 0
A8: terça-feira, 10 de janeiro de 2023 | B8: 14 | C8: 13 | D8: 0 | E8: 0 | F8: 5 | G8: 8 | H8: 0 | I8: 0
A9: quarta-feira, 11 de janeiro de 2023 | B9: 12 | C9: 8 | D9: 4 | E9: 0 | F9: 0 | G9: 4 | H9: 0 | I9: 0
A10: quinta-feira, 12 de janeiro de 2023 | B10: 7 | C10: 6 | D10: 0 | E10: 0 | F10: 1 | G10: 5 | H10: 0 | I10: 0
A11: sexta-feira, 13 de janeiro de 2023 | B11: 9 | C11: 8 | D11: 0 | E11: 0 | F11: 4 | G11: 3 | H11: 0 | I11: 1
A12: segunda-feira, 16 de janeiro de 2023 | B12: 14 | C12: 13 | D12: 1 | E12: 0 | F12: 3 | G12: 9 | H12: 0 | I12: 0
A13: terça-feira, 17 de janeiro de 2023 | B13: 8 | C13: 10 | D13: 1 | E13: 0 | F13: 3 | G13: 6 | H13: 0 | I13: 0
... A23: terça-feira, 31 de janeiro de 2023 | B23: 3 | C23: 11 | D23: 1 | E23: 2 | F23: 0 | G23: 8 | H23: 0 | I23: 0
A24: Médias Diárias | B24: =AVERAGE(B2:B23) -> 9.2272727 | C24: =AVERAGE(C2:C23) -> 8.5454545 | D24: =AVERAGE(D2:D23) -> 0.86363636 | E24: =AVERAGE(E2:E23) -> 0.5 | F24: =AVERAGE(F2:F23) -> 1.5454545 | G24: =AVERAGE(G2:G23) -> 5.2727273 | H24: =AVERAGE(H2:H23) -> 0 | I24: =AVERAGE(I2:I23) -> 0.36363636
A25: Somatórias | B25: =SUM(B2:B23) -> 203 | C25: =SUM(C2:C23) -> 188 | D25: =SUM(D2:D23) -> 19 | E25: =SUM(E2:E23) -> 11 | F25: =SUM(F2:F23) -> 34 | G25: =SUM(G2:G23) -> 116 | H25: =SUM(H2:H23) -> 0 | I25: =SUM(I2:I23) -> 8
A26: Porcentagem | D26: =(D25*100)/C25 -> 10.106383 | E26: =(E25*100)/C25 -> 5.8510638 | F26: =(F25*100)/C25 -> 18.085106 | G26: =(G25*100)/C25 -> 61.702128 | H26: =(H25*100)/C25 -> 0 | I26: =(I25*100)/C25 -> 4.2553191

Sheet Fev-23
A1: Data | B1: Created | C1: Resolved | D1: Fernando | E1: Everton | F1: Rapahel | G1: Andre | H1: Não atribuídos | I1: Camille
A2: 1 de fev. de 2023 | B2: 2 | C2: 5 | D2: 0 | E2: 4 | F2: 0 | G2: 1 | H2: 0 | I2: 0
A3: 2 de fev. de 2023 | B3: 4 | C3: 5 | D3: 2 | E3: 0 | F3: 2 | G3: 1 | H3: 0 | I3: 0
A4: 3 de fev. de 2023 | B4: 14 | C4: 10 | D4: 1 | E4: 4 | F4: 3 | G4: 2 | H4: 0 | I4: 0
A5: 6 de fev. de 2023 | B5: 11 | C5: 4 | D5: 0 | E5: 1 | F5: 2 | G5: 1 | H5: 0 | I5: 0
A6: 7 de fev. de 2023 | B6: 9 | C6: 13 | D6: 0 | E6: 1 | F6: 5 | G6: 7 | H6: 0 | I6: 0
A7: 8 de fev. de 2023 | B7: 19 | C7: 16 | D7: 1 | E7: 3 | F7: 3 | G7: 9 | H7: 0 | I7: 0
A8: 9 de fev. de 2023 | B8: 11 | C8: 10 | D8: 2 | E8: 3 | F8: 2 | G8: 3 | H8: 0 | I8: 0
A9: 10 de fev. de 2023 | B9: 15 | C9: 12 | D9: 1 | E9: 1 | F9: 3 | G9: 7 | H9: 0 | I9: 0
A10: 13 de fev. de 2023 | B10: 13 | C10: 10 | D10: 0 | E10: 1 | F10: 1 | G10: 6 | H10: 0 | I10: 2
A11: 14 de fev. de 2023 | B11: 12 | C11: 18 | D11: 0 | E11: 0 | F11: 4 | G11: 12 | H11: 0 | I11: 2
A12: 15 de fev. de 2023 | B12: 5 | C12: 7 | D12: 0 | E12: 5 | F12: 1 | G12: 1 | H12: 0 | I12: 0
A13: 16 de fev. de 2023 | B13: 13 | C13: 9 | D13: 0 | E13: 2 | F13: 1 | G13: 6 | H13: 0 | I13: 0
... A19: 28 de fev. de 2023 | B19: 17 | C19: 21 | D19: 3 | E19: 4 | F19: 5 | G19: 9 | H19: 0 | I19: 0
A20: Médias Diárias | B20: =AVERAGE(B2:B19) -> 10.666667 | C20: =AVERAGE(C2:C19) -> 10.611111 | D20: =AVERAGE(D2:D19) -> 0.94444444 | E20: =AVERAGE(E2:E19) -> 1.7222222 | F20: =AVERAGE(F2:F19) -> 2.3333333 | G20: =AVERAGE(G2:G19) -> 5.3333333 | H20: =AVERAGE(H2:H19) -> 0 | I20: =AVERAGE(I2:I19) -> 0.27777778
A21: Somatórias | B21: =SUM(B2:B19) -> 192 | C21: =SUM(C2:C19) -> 191 | D21: =SUM(D2:D19) -> 17 | E21: =SUM(E2:E19) -> 31 | F21: =SUM(F2:F19) -> 42 | G21: =SUM(G2:G19) -> 96 | H21: =SUM(H2:H19) -> 0 | I21: =SUM(I2:I19) -> 5
A22: Porcentagem | D22: =(D21*100)/C21 -> 8.9005236 | E22: =(E21*100)/C21 -> 16.230366 | F22: =(F21*100)/C21 -> 21.989529 | G22: =(G21*100)/C21 -> 50.26178 | H22: =(H21*100)/C21 -> 0 | I22: =(I21*100)/C21 -> 2.617801

Sheet Mar-23
A1: Data | B1: Created | C1: Resolved | D1: Fernando | E1: Everton | F1: Rapahel | G1: Andre | H1: Não atribuídos | I1: Camille
A2: 1 de mar. | B2: 20 | C2: 20 | D2: 0 | E2: 7 | F2: 3 | G2: 10 | H2: 0 | I2: 0
A3: 2 de mar. | B3: 16 | C3: 15 | D3: 0 | E3: 1 | F3: 4 | G3: 10 | H3: 0 | I3: 0
A4: 3 de mar. | B4: 26 | C4: 13 | D4: 0 | E4: 3 | F4: 2 | G4: 3 | H4: 0 | I4: 5
A5: 6 de mar. | B5: 7 | C5: 12 | D5: 0 | E5: 0 | F5: 6 | G5: 4 | H5: 0 | I5: 2
A6: 7 de mar. | B6: 11 | C6: 13 | D6: 4 | E6: 2 | F6: 4 | G6: 3 | H6: 0 | I6: 0
A7: 8 de mar. | B7: 11 | C7: 10 | D7: 0 | E7: 5 | F7: 1 | G7: 4 | H7: 0 | I7: 0
A8: 9 de mar. | B8: 8 | C8: 13 | D8: 2 | E8: 3 | F8: 3 | G8: 5 | H8: 0 | I8: 0
A9: 10 de mar. | B9: 4 | C9: 5 | D9: 1 | E9: 1 | F9: 1 | G9: 2 | H9: 0 | I9: 0
A10: 13 de mar. | B10: 13 | C10: 11 | D10: 2 | E10: 2 | F10: 0 | G10: 7 | H10: 0 | I10: 0
A11: 14 de mar. | B11: 12 | C11: 13 | D11: 0 | E11: 0 | F11: 3 | G11: 10 | H11: 0 | I11: 0
A12: 15 de mar. | B12: 11 | C12: 9 | D12: 0 | E12: 3 | F12: 4 | G12: 2 | H12: 0 | I12: 0
A13: 16 de mar. | B13: 9 | C13: 11 | D13: 0 | E13: 1 | F13: 4 | G13: 6 | H13: 0 | I13: 0
... A25: 31 de mar. | B25: 14 | C25: 16 | D25: 1 | E25: 3 | F25: 1 | G25: 5 | H25: 0 | I25: 6
A26: Médias Diárias | B26: =AVERAGE(B2:B25) -> 11.958333 | C26: =AVERAGE(C2:C25) -> 12.166667 | D26: =AVERAGE(D2:D25) -> 1.0833333 | E26: =AVERAGE(E2:E25) -> 1.8333333 | F26: =AVERAGE(F2:F25) -> 2.3333333 | G26: =AVERAGE(G2:G25) -> 5.7916667 | H26: =AVERAGE(H2:H25) -> 0 | I26: =AVERAGE(I2:I25) -> 1.125
A27: Somatórias | B27: =SUM(B2:B25) -> 287 | C27: =SUM(C2:C25) -> 292 | D27: =SUM(D2:D25) -> 26 | E27: =SUM(E2:E25) -> 44 | F27: =SUM(F2:F25) -> 56 | G27: =SUM(G2:G25) -> 139 | H27: =SUM(H2:H25) -> 0 | I27: =SUM(I2:I25) -> 27
A28: Porcentagem | D28: =(D27*100)/C27 -> 8.9041096 | E28: =(E27*100)/C27 -> 15.068493 | F28: =(F27*100)/C27 -> 19.178082 | G28: =(G27*100)/C27 -> 47.60274 | H28: =(H27*100)/C27 -> 0 | I28: =(I27*100)/C27 -> 9.2465753

Sheet Abr-23
A1: Data | B1: Created | C1: Resolved | D1: Fernando | E1: Everton | F1: Rapahel | G1: Andre | H1: Não atribuídos | I1: Camille
A2: 3 de abr. de 2023 | B2: 10 | C2: 9 | D2: 3 | E2: 2 | F2: 0 | G2: 1 | H2: 0 | I2: 3
A3: 4 de abr. de 2023 | B3: 4 | C3: 7 | D3: 0 | E3: 4 | F3: 0 | G3: 3 | H3: 0 | I3: 0
A4: 5 de abr. de 2023 | B4: 11 | C4: 7 | D4: 1 | E4: 0 | F4: 0 | G4: 6 | H4: 0 | I4: 0
A5: 6 de abr. de 2023 | B5: 11 | C5: 15 | D5: 0 | E5: 5 | F5: 0 | G5: 9 | H5: 0 | I5: 1
A6: 10 de abr. de 2023 | B6: 12 | C6: 11 | D6: 0 | E6: 2 | F6: 1 | G6: 5 | H6: 0 | I6: 3
A7: 11 de abr. de 2023 | B7: 19 | C7: 14 | D7: 0 | E7: 1 | F7: 5 | G7: 8 | H7: 0 | I7: 0
A8: 12 de abr. de 2023 | B8: 5 | C8: 12 | D8: 1 | E8: 3 | F8: 2 | G8: 5 | H8: 0 | I8: 1
A9: 13 de abr. de 2023 | B9: 10 | C9: 9 | D9: 0 | E9: 0 | F9: 2 | G9: 6 | H9: 0 | I9: 1
A10: 14 de abr. de 2023 | B10: 7 | C10: 7 | D10: 1 | E10: 1 | F10: 0 | G10: 3 | H10: 0 | I10: 2
A11: 17 de abr. de 2023 | B11: 5 | C11: 3 | D11: 0 | E11: 1 | F11: 0 | G11: 2 | H11: 0 | I11: 0
A12: 18 de abr. de 2023 | B12: 13 | C12: 11 | D12: 1 | E12: 0 | F12: 1 | G12: 8 | H12: 0 | I12: 1
A13: 19 de abr. de 2023 | B13: 18 | C13: 14 | D13: 0 | E13: 1 | F13: 3 | G13: 8 | H13: 0 | I13: 2
... A20: 29 de abr. de 2023 | B20: 1 | C20: 1 | D20: 0 | E20: 1 | F20: 0 | G20: 0 | H20: 0 | I20: 0
A21: Médias Diárias | B21: =AVERAGE(B2:B20) -> 11 | C21: =AVERAGE(C2:C20) -> 11.157895 | D21: =AVERAGE(D2:D20) -> 0.73684211 | E21: =AVERAGE(E2:E20) -> 2.2105263 | F21: =AVERAGE(F2:F20) -> 1.3684211 | G21: =AVERAGE(G2:G20) -> 5.3684211 | H21: =AVERAGE(H2:H20) -> 0 | I21: =AVERAGE(I2:I20) -> 1.4736842
A22: Somatórias | B22: =SUM(B2:B20) -> 209 | C22: =SUM(C2:C20) -> 212 | D22: =SUM(D2:D20) -> 14 | E22: =SUM(E2:E20) -> 42 | F22: =SUM(F2:F20) -> 26 | G22: =SUM(G2:G20) -> 102 | H22: =SUM(H2:H20) -> 0 | I22: =SUM(I2:I20) -> 28
A23: Porcentagem | D23: =(D22*100)/C22 -> 6.6037736 | E23: =(E22*100)/C22 -> 19.811321 | F23: =(F22*100)/C22 -> 12.264151 | G23: =(G22*100)/C22 -> 48.113208 | H23: =(H22*100)/C22 -> 0 | I23: =(I22*100)/C22 -> 13.207547

Sheet Mai-23
A1: Data | B1: Created | C1: Resolved | D1: Fernando | E1: Everton | F1: Rapahel | G1: Andre | H1: Não atribuídos | I1: Camille
A2: 2 de mai. | B2: 9 | C2: 14 | D2: 1 | E2: 2 | F2: 5 | G2: 5 | H2: 0 | I2: 1
A3: 3 de mai. | B3: 13 | C3: 13 | D3: 0 | E3: 5 | F3: 3 | G3: 5 | H3: 0 | I3: 0
A4: 4 de mai. | B4: 22 | C4: 17 | D4: 2 | E4: 1 | F4: 3 | G4: 5 | H4: 0 | I4: 6
A5: 5 de mai. | B5: 11 | C5: 13 | D5: 0 | E5: 3 | F5: 1 | G5: 6 | H5: 0 | I5: 3
A6: 8 de mai. | B6: 7 | C6: 10 | D6: 0 | E6: 1 | F6: 2 | G6: 5 | H6: 0 | I6: 2
A7: 9 de mai. | B7: 14 | C7: 13 | D7: 0 | E7: 4 | F7: 1 | G7: 7 | H7: 0 | I7: 1
A8: 10 de mai. | B8: 10 | C8: 9 | D8: 1 | E8: 0 | F8: 2 | G8: 2 | H8: 0 | I8: 4
A9: 11 de mai. | B9: 13 | C9: 11 | D9: 1 | E9: 0 | F9: 4 | G9: 4 | H9: 0 | I9: 2
A10: 12 de mai. | B10: 12 | C10: 12 | D10: 0 | E10: 1 | F10: 1 | G10: 4 | H10: 0 | I10: 6
A11: 15 de mai. | B11: 10 | C11: 12 | D11: 1 | E11: 2 | F11: 0 | G11: 5 | H11: 0 | I11: 4
A12: 16 de mai. | B12: 13 | C12: 13 | D12: 0 | E12: 1 | F12: 1 | G12: 9 | H12: 0 | I12: 2
A13: 17 de mai. | B13: 8 | C13: 9 | D13: 0 | E13: 2 | F13: 1 | G13: 4 | H13: 0 | I13: 2
... A23: 31 de mai. | B23: 16 | C23: 17 | D23: 2 | E23: 4 | F23: 3 | G23: 7 | H23: 0 | I23: 1
A24: Médias Diárias | B24: =AVERAGE(B2:B23) -> 11.818182 | C24: =AVERAGE(C2:C23) -> 12.136364 | D24: =AVERAGE(D2:D23) -> 0.36363636 | E24: =AVERAGE(E2:E23) -> 1.7272727 | F24: =AVERAGE(F2:F23) -> 2.0454545 | G24: =AVERAGE(G2:G23) -> 5.4090909 | H24: =AVERAGE(H2:H23) -> 0 | I24: =AVERAGE(I2:I23) -> 2.5909091
A25: Somatórias | B25: =SUM(B2:B23) -> 260 | C25: =SUM(C2:C23) -> 267 | D25: =SUM(D2:D23) -> 8 | E25: =SUM(E2:E23) -> 38 | F25: =SUM(F2:F23) -> 45 | G25: =SUM(G2:G23) -> 119 | H25: =SUM(H2:H23) -> 0 | I25: =SUM(I2:I23) -> 57
A26: Porcentagem | D26: =(D25*100)/C25 -> 2.9962547 | E26: =(E25*100)/C25 -> 14.23221 | F26: =(F25*100)/C25 -> 16.853933 | G26: =(G25*100)/C25 -> 44.569288 | H26: =(H25*100)/C25 -> 0 | I26: =(I25*100)/C25 -> 21.348315

Sheet Jun-23
A1: Data | B1: Created | C1: Resolved | D1: Fernando | E1: Everton | F1: Rapahel | G1: Andre | H1: Não atribuídos | I1: Camille
A2: 45078 | B2: 18 | C2: 18 | D2: 5 | E2: 4 | F2: 1 | G2: 6 | H2: 0 | I2: 2
A3: 45079 | B3: 23 | C3: 16 | D3: 0 | E3: 3 | F3: 7 | G3: 2 | H3: 0 | I3: 4
A4: 45082 | B4: 10 | C4: 20 | D4: 0 | E4: 3 | F4: 11 | G4: 6 | H4: 0 | I4: 0
A5: 45083 | B5: 6 | C5: 5 | D5: 0 | E5: 0 | F5: 2 | G5: 2 | H5: 0 | I5: 1
A6: 45084 | B6: 6 | C6: 7 | D6: 0 | E6: 3 | F6: 2 | G6: 1 | H6: 0 | I6: 1
A7: 45085 | B7: 0 | C7: 1 | D7: 0 | E7: 1 | F7: 0 | G7: 0 | H7: 0 | I7: 0
A8: 45086 | B8: 14 | C8: 9 | D8: 3 | E8: 0 | F8: 1 | G8: 5 | H8: 0 | I8: 0
A9: 45089 | B9: 18 | C9: 8 | D9: 2 | E9: 1 | F9: 1 | G9: 2 | H9: 0 | I9: 2
A10: 45090 | B10: 16 | C10: 29 | D10: 1 | E10: 3 | F10: 4 | G10: 20 | H10: 0 | I10: 1
A11: 45091 | B11: 18 | C11: 13 | D11: 2 | E11: 1 | F11: 2 | G11: 6 | H11: 0 | I11: 2
A12: 45092 | B12: 11 | C12: 12 | D12: 1 | E12: 2 | F12: 3 | G12: 4 | H12: 0 | I12: 2
A13: 45093 | B13: 16 | C13: 13 | D13: 1 | E13: 1 | F13: 0 | G13: 5 | H13: 0 | I13: 6
... A23: 45107 | B23: 14 | C23: 16 | D23: 3 | E23: 6 | F23: 1 | G23: 2 | H23: 0 | I23: 4
A24: Médias Diárias | B24: =AVERAGE(B2:B23) -> 12.590909 | C24: =AVERAGE(C2:C23) -> 12.045455 | D24: =AVERAGE(D2:D23) -> 1 | E24: =AVERAGE(E2:E23) -> 2.1363636 | F24: =AVERAGE(F2:F23) -> 1.9545455 | G24: =AVERAGE(G2:G23) -> 5.1818182 | H24: =AVERAGE(H2:H23) -> 0 | I24: =AVERAGE(I2:I23) -> 1.7727273
A25: Somatórias | B25: =SUM(B2:B23) -> 277 | C25: =SUM(C2:C23) -> 265 | D25: =SUM(D2:D23) -> 22 | E25: =SUM(E2:E23) -> 47 | F25: =SUM(F2:F23) -> 43 | G25: =SUM(G2:G23) -> 114 | H25: =SUM(H2:H23) -> 0 | I25: =SUM(I2:I23) -> 39
A26: Porcentagem | D26: =(D25*100)/C25 -> 8.3018868 | E26: =(E25*100)/C25 -> 17.735849 | F26: =(F25*100)/C25 -> 16.226415 | G26: =(G25*100)/C25 -> 43.018868 | H26: =(H25*100)/C25 -> 0 | I26: =(I25*100)/C25 -> 14.716981

Sheet Jul-23
A1: Data | B1: Created | C1: Resolved | D1: Fernando | E1: Everton | F1: Raphael | G1: Andre | H1: Não atribuídos | I1: Camille
A2: segunda-feira, 3 de julho de 2023 | B2: 13 | C2: 13 | D2: 0 | E2: 2 | F2: 3 | G2: 6 | H2: 0 | I2: 2
A3: terça-feira, 4 de julho de 2023 | B3: 13 | C3: 15 | D3: 0 | E3: 1 | F3: 2 | G3: 10 | H3: 0 | I3: 2
A4: quarta-feira, 5 de julho de 2023 | B4: 10 | C4: 11 | D4: 1 | E4: 2 | F4: 2 | G4: 5 | H4: 0 | I4: 1
A5: quinta-feira, 6 de julho de 2023 | B5: 14 | C5: 8 | D5: 2 | E5: 0 | F5: 4 | G5: 1 | H5: 0 | I5: 1
A6: sexta-feira, 7 de julho de 2023 | B6: 11 | C6: 11 | D6: 1 | E6: 2 | F6: 0 | G6: 6 | H6: 0 | I6: 2
A7: segunda-feira, 10 de julho de 2023 | B7: 9 | C7: 10 | D7: 0 | E7: 1 | F7: 0 | G7: 4 | H7: 0 | I7: 5
A8: terça-feira, 11 de julho de 2023 | B8: 6 | C8: 7 | D8: 0 | E8: 1 | F8: 2 | G8: 3 | H8: 0 | I8: 1
A9: quarta-feira, 12 de julho de 2023 | B9: 9 | C9: 13 | D9: 0 | E9: 2 | F9: 2 | G9: 6 | H9: 0 | I9: 3
A10: quinta-feira, 13 de julho de 2023 | B10: 5 | C10: 6 | D10: 0 | E10: 1 | F10: 4 | G10: 1 | H10: 0 | I10: 0
A11: sexta-feira, 14 de julho de 2023 | B11: 5 | C11: 6 | D11: 0 | E11: 0 | F11: 0 | G11: 3 | H11: 0 | I11: 3
A12: segunda-feira, 17 de julho de 2023 | B12: 6 | C12: 9 | D12: 0 | E12: 3 | F12: 0 | G12: 6 | H12: 0 | I12: 0
A13: terça-feira, 18 de julho de 2023 | B13: 6 | C13: 7 | D13: 0 | E13: 1 | F13: 2 | G13: 4 | H13: 0 | I13: 0
... A22: segunda-feira, 31 de julho de 2023 | B22: 12 | C22: 10 | D22: 0 | E22: 2 | F22: 7 | G22: 0 | H22: 0 | I22: 1
A23: Médias Diárias | B23: =AVERAGE(B1:B22) -> 8.6666667 | C23: =AVERAGE(C1:C22) -> 8.6190476 | D23: =AVERAGE(D1:D22) -> 0.38095238 | E23: =AVERAGE(E1:E22) -> 1.1428571 | F23: =AVERAGE(F1:F22) -> 2 | G23: =AVERAGE(G1:G22) -> 4.0952381 | H23: =AVERAGE(H1:H22) -> 0 | I23: =AVERAGE(I1:I22) -> 1
A24: Somatórias | B24: =SUM(B1:B22) -> 182 | C24: =SUM(C1:C22) -> 181 | D24: =SUM(D1:D22) -> 8 | E24: =SUM(E1:E22) -> 24 | F24: =SUM(F1:F22) -> 42 | G24: =SUM(G1:G22) -> 86 | H24: =SUM(H1:H22) -> 0 | I24: =SUM(I1:I22) -> 21
A25: Porcentagem | D25: =(D24*100)/C24 -> 4.4198895 | E25: =(E24*100)/C24 -> 13.259669 | F25: =(F24*100)/C24 -> 23.20442 | G25: =(G24*100)/C24 -> 47.513812 | H25: =(H24*100)/C24 -> 0 | I25: =(I24*100)/C24 -> 11.60221

Sheet Ago-23
A1: Data | B1: Created | C1: Resolved | D1: Fernando | E1: Everton | F1: Raphael | G1: Andre | H1: Não atribuídos | I1: Camille
A2: terça-feira, 1 de agosto de 2023 | B2: 10 | C2: 9 | D2: 0 | E2: 5 | F2: 3 | G2: 0 | H2: 0 | I2: 1
A3: quarta-feira, 2 de agosto de 2023 | B3: 13 | C3: 16 | D3: 0 | E3: 8 | F3: 6 | G3: 0 | H3: 0 | I3: 2
A4: quinta-feira, 3 de agosto de 2023 | B4: 9 | C4: 7 | D4: 1 | E4: 1 | F4: 5 | G4: 0 | H4: 0 | I4: 0
A5: sexta-feira, 4 de agosto de 2023 | B5: 9 | C5: 7 | D5: 1 | E5: 0 | F5: 3 | G5: 0 | H5: 0 | I5: 3
A6: segunda-feira, 7 de agosto de 2023 | B6: 4 | C6: 6 | D6: 0 | E6: 0 | F6: 2 | G6: 1 | H6: 0 | I6: 3
A7: terça-feira, 8 de agosto de 2023 | B7: 6 | C7: 6 | D7: 1 | E7: 1 | F7: 2 | G7: 2 | H7: 0 | I7: 0
A8: quarta-feira, 9 de agosto de 2023 | B8: 9 | C8: 3 | D8: 0 | E8: 1 | F8: 0 | G8: 2 | H8: 0 | I8: 0
A9: quinta-feira, 10 de agosto de 2023 | B9: 8 | C9: 12 | D9: 0 | E9: 4 | F9: 1 | G9: 4 | H9: 0 | I9: 3
A10: sexta-feira, 11 de agosto de 2023 | B10: 9 | C10: 12 | D10: 1 | E10: 1 | F10: 6 | G10: 2 | H10: 0 | I10: 2
A11: segunda-feira, 14 de agosto de 2023 | B11: 12 | C11: 10 | D11: 0 | E11: 2 | F11: 4 | G11: 2 | H11: 0 | I11: 2
A12: terça-feira, 15 de agosto de 2023 | B12: 22 | C12: 20 | D12: 0 | E12: 2 | F12: 2 | G12: 11 | H12: 0 | I12: 5
A13: quarta-feira, 16 de agosto de 2023 | B13: 18 | C13: 23 | D13: 4 | E13: 4 | F13: 2 | G13: 1 | H13: 0 | I13: 12
... A24: quinta-feira, 31 de agosto de 2023 | B24: 8 | C24: 3 | D24: 0 | E24: 0 | F24: 1 | G24: 1 | H24: 0 | I24: 1
A25: Médias Diárias | B25: =AVERAGE(B2:B24) -> 10.086957 | C25: =AVERAGE(C2:C24) -> 9.3913043 | D25: =AVERAGE(D2:D24) -> 0.47826087 | E25: =AVERAGE(E2:E24) -> 1.7826087 | F25: =AVERAGE(F2:F24) -> 2.3913043 | G25: =AVERAGE(G2:G24) -> 2.3913043 | H25: =AVERAGE(H2:H24) -> 0 | I25: =AVERAGE(I2:I24) -> 2.3478261
A26: Somatórias | B26: =SUM(B2:B24) -> 232 | C26: =SUM(C2:C24) -> 216 | D26: =SUM(D2:D24) -> 11 | E26: =SUM(E2:E24) -> 41 | F26: =SUM(F2:F24) -> 55 | G26: =SUM(G2:G24) -> 55 | H26: =SUM(H2:H24) -> 0 | I26: =SUM(I2:I24) -> 54
A27: Porcentagem | D27: =(D26*100)/C26 -> 5.0925926 | E27: =(E26*100)/C26 -> 18.981481 | F27: =(F26*100)/C26 -> 25.462963 | G27: =(G26*100)/C26 -> 25.462963 | H27: =(H26*100)/C26 -> 0 | I27: =(I26*100)/C26 -> 25

Sheet Set-23
A1: Data | B1: Created | C1: Resolved | D1: Fernando | E1: Everton | F1: Raphael | G1: Andre | H1: Não atribuídos | I1: Camille | J1: Jean
A2: sexta-feira, 1 de setembro de 2023 | B2: 4 | C2: 5 | D2: 0 | E2: 0 | F2: 1 | G2: 2 | H2: 0 | I2: 2 | J2: 0
A3: segunda-feira, 4 de setembro de 2023 | B3: 25 | C3: 17 | D3: 0 | E3: 0 | F3: 2 | G3: 11 | H3: 0 | I3: 4 | J3: 0
A4: terça-feira, 5 de setembro de 2023 | B4: 9 | C4: 22 | D4: 8 | E4: 3 | F4: 2 | G4: 8 | H4: 0 | I4: 1 | J4: 0
A5: quarta-feira, 6 de setembro de 2023 | B5: 10 | C5: 6 | D5: 0 | E5: 1 | F5: 3 | G5: 1 | H5: 0 | I5: 1 | J5: 0
A6: sexta-feira, 8 de setembro de 2023 | B6: 7 | C6: 7 | D6: 0 | E6: 0 | F6: 4 | G6: 3 | H6: 0 | I6: 0 | J6: 0
A7: segunda-feira, 11 de setembro de 2023 | B7: 5 | C7: 12 | D7: 0 | E7: 2 | F7: 3 | G7: 4 | H7: 0 | I7: 3 | J7: 0
A8: terça-feira, 12 de setembro de 2023 | B8: 4 | C8: 7 | D8: 0 | E8: 0 | F8: 0 | G8: 4 | H8: 0 | I8: 3 | J8: 0
A9: quarta-feira, 13 de setembro de 2023 | B9: 7 | C9: 4 | D9: 0 | E9: 0 | F9: 0 | G9: 1 | H9: 0 | I9: 3 | J9: 0
A10: quinta-feira, 14 de setembro de 2023 | B10: 9 | C10: 4 | D10: 0 | E10: 1 | F10: 1 | G10: 2 | H10: 0 | I10: 0 | J10: 0
A11: sexta-feira, 15 de setembro de 2023 | B11: 9 | C11: 11 | D11: 4 | E11: 1 | F11: 0 | G11: 6 | H11: 0 | I11: 0 | J11: 0
A12: segunda-feira, 18 de setembro de 2023 | B12: 9 | C12: 7 | D12: 0 | E12: 1 | F12: 2 | G12: 3 | H12: 0 | I12: 1 | J12: 0
A13: terça-feira, 19 de setembro de 2023 | B13: 11 | C13: 7 | D13: 0 | E13: 0 | F13: 4 | G13: 1 | H13: 0 | I13: 2 | J13: 0
... A21: sexta-feira, 29 de setembro de 2023 | B21: 6 | C21: 6 | D21: 0 | E21: 2 | F21: 3 | G21: 0 | H21: 0 | I21: 0 | J21: 1
A22: Médias Diárias | B22: =AVERAGE(B2:B21) -> 9.25 | C22: =AVERAGE(C2:C21) -> 9.05 | D22: =AVERAGE(D2:D21) -> 0.75 | E22: =AVERAGE(E2:E21) -> 1 | F22: =AVERAGE(F2:F21) -> 2.25 | G22: =AVERAGE(G2:G21) -> 3.55 | H22: =AVERAGE(H2:H21) -> 0 | I22: =AVERAGE(I2:I21) -> 1.45 | J22: =AVERAGE(J2:J21) -> 0.05
A23: Somatórias | B23: =SUM(B2:B21) -> 185 | C23: =SUM(C2:C21) -> 181 | D23: =SUM(D2:D21) -> 15 | E23: =SUM(E2:E21) -> 20 | F23: =SUM(F2:F21) -> 45 | G23: =SUM(G2:G21) -> 71 | H23: =SUM(H2:H21) -> 0 | I23: =SUM(I2:I21) -> 29 | J23: =SUM(J2:J21) -> 1
A24: Porcentagem | D24: =(D23*100)/C23 -> 8.2872928 | E24: =(E23*100)/C23 -> 11.049724 | F24: =(F23*100)/C23 -> 24.861878 | G24: =(G23*100)/C23 -> 39.226519 | H24: =(H23*100)/C23 -> 0 | I24: =(I23*100)/C23 -> 16.022099 | J24: =(J23*100)/C23 -> 0.55248619

Sheet Out-23
A1: Data | B1: Created | C1: Resolved | D1: Fernando | E1: Everton | F1: Raphael | G1: Andre | H1: Não atribuídos | I1: Camille | J1: Jean
A2: segunda-feira, 2 de outubro de 2023 | B2: 7 | C2: 7 | D2: 0 | E2: 0 | F2: 4 | G2: 0 | H2: 0 | I2: 0 | J2: 3
A3: terça-feira, 3 de outubro de 2023 | B3: 3 | C3: 3 | D3: 0 | E3: 0 | F3: 1 | G3: 0 | H3: 0 | I3: 0 | J3: 2
A4: quarta-feira, 4 de outubro de 2023 | B4: 2 | C4: 4 | D4: 0 | E4: 0 | F4: 0 | G4: 0 | H4: 0 | I4: 2 | J4: 2
A5: quinta-feira, 5 de outubro de 2023 | B5: 9 | C5: 4 | D5: 0 | E5: 1 | F5: 0 | G5: 0 | H5: 0 | I5: 0 | J5: 3
A6: sexta-feira, 6 de outubro de 2023 | B6: 9 | C6: 13 | D6: 0 | E6: 2 | F6: 4 | G6: 0 | H6: 0 | I6: 3 | J6: 4
A7: segunda-feira, 9 de outubro de 2023 | B7: 12 | C7: 13 | D7: 0 | E7: 2 | F7: 0 | G7: 0 | H7: 0 | I7: 10 | J7: 1
A8: terça-feira, 10 de outubro de 2023 | B8: 6 | C8: 4 | D8: 0 | E8: 0 | F8: 3 | G8: 0 | H8: 0 | I8: 0 | J8: 1
A9: quarta-feira, 11 de outubro de 2023 | B9: 6 | C9: 7 | D9: 0 | E9: 2 | F9: 2 | G9: 0 | H9: 0 | I9: 0 | J9: 3
A10: quinta-feira, 12 de outubro de 2023 | B10: 0 | C10: 0 | D10: 0 | E10: 0 | F10: 0 | G10: 0 | H10: 0 | I10: 0 | J10: 0
A11: sexta-feira, 13 de outubro de 2023 | B11: 2 | C11: 1 | D11: 0 | E11: 0 | F11: 0 | G11: 0 | H11: 0 | I11: 0 | J11: 1
A12: segunda-feira, 16 de outubro de 2023 | B12: 5 | C12: 12 | D12: 0 | E12: 0 | F12: 8 | G12: 3 | H12: 0 | I12: 1 | J12: 0
A13: terça-feira, 17 de outubro de 2023 | B13: 12 | C13: 13 | D13: 0 | E13: 1 | F13: 4 | G13: 2 | H13: 0 | I13: 2 | J13: 4
... A23: terça-feira, 31 de outubro de 2023 | B23: 10 | C23: 8 | D23: 0 | E23: 1 | F23: 2 | G23: 0 | H23: 0 | I23: 1 | J23: 4
A24: Médias Diárias | B24: =AVERAGE(B2:B23) -> 7.5454545 | C24: =AVERAGE(C2:C23) -> 7.6818182 | D24: =AVERAGE(D2:D23) -> 0 | E24: =AVERAGE(E2:E23) -> 0.86363636 | F24: =AVERAGE(F2:F23) -> 2.7272727 | G24: =AVERAGE(G12:G23) -> 1.25 | H24: =AVERAGE(H2:H23) -> 0 | I24: =AVERAGE(I2:I23) -> 1.4545455 | J24: =AVERAGE(J2:J23) -> 1.9545455
A25: Somatórias | B25: =SUM(B2:B23) -> 166 | C25: =SUM(C2:C23) -> 169 | D25: =SUM(D2:D23) -> 0 | E25: =SUM(E2:E23) -> 19 | F25: =SUM(F2:F23) -> 60 | G25: =SUM(G2:G23) -> 15 | H25: =SUM(H2:H23) -> 0 | I25: =SUM(I2:I23) -> 32 | J25: =SUM(J2:J23) -> 43
A26: Porcentagem | D26: =(D25*100)/C25 -> 0 | E26: =(E25*100)/C25 -> 11.242604 | F26: =(F25*100)/C25 -> 35.502959 | G26: =(G25*100)/C25 -> 8.8757396 | H26: =(H25*100)/C25 -> 0 | I26: =(I25*100)/C25 -> 18.934911 | J26: =(J25*100)/C25 -> 25.443787

Sheet Nov-23
A1: Data | B1: Created | C1: Resolved | D1: Everton | E1: Raphael | F1: Andre | G1: Não atribuídos | H1: Camille | I1: Jean
A2: quarta-feira, 1 de novembro de 2023 | B2: 26 | C2: 3 | D2: 1 | E2: 1 | F2: 1 | G2: 0 | H2: 0 | I2: 0
A3: sexta-feira, 3 de novembro de 2023 | B3: 8 | C3: 9 | D3: 2 | E3: 2 | F3: 1 | G3: 0 | H3: 0 | I3: 4
A4: segunda-feira, 6 de novembro de 2023 | B4: 3 | C4: 10 | D4: 2 | E4: 4 | F4: 1 | G4: 0 | H4: 0 | I4: 3
A5: terça-feira, 7 de novembro de 2023 | B5: 12 | C5: 6 | D5: 0 | E5: 1 | F5: 0 | G5: 0 | H5: 2 | I5: 3
A6: quarta-feira, 8 de novembro de 2023 | B6: 5 | C6: 3 | D6: 0 | E6: 1 | F6: 0 | G6: 0 | H6: 2 | I6: 0
A7: quinta-feira, 9 de novembro de 2023 | B7: 10 | C7: 10 | D7: 0 | E7: 3 | F7: 2 | G7: 0 | H7: 1 | I7: 4
A8: sexta-feira, 10 de novembro de 2023 | B8: 14 | C8: 14 | D8: 0 | E8: 8 | F8: 2 | G8: 0 | H8: 1 | I8: 3
A9: segunda-feira, 13 de novembro de 2023 | B9: 7 | C9: 13 | D9: 2 | E9: 1 | F9: 9 | G9: 0 | H9: 1 | I9: 0
A10: terça-feira, 14 de novembro de 2023 | B10: 8 | C10: 7 | D10: 1 | E10: 2 | F10: 3 | G10: 0 | H10: 0 | I10: 1
A11: quinta-feira, 16 de novembro de 2023 | B11: 11 | C11: 24 | D11: 1 | E11: 2 | F11: 11 | G11: 0 | H11: 7 | I11: 3
A12: sexta-feira, 17 de novembro de 2023 | B12: 12 | C12: 8 | D12: 0 | E12: 0 | F12: 4 | G12: 0 | H12: 0 | I12: 4
A13: terça-feira, 21 de novembro de 2023 | B13: 10 | C13: 11 | D13: 3 | E13: 0 | F13: 4 | G13: 0 | H13: 1 | I13: 3
... A20: quinta-feira, 30 de novembro de 2023 | B20: 7 | C20: 5 | D20: 1 | E20: 1 | F20: 2 | G20: 0 | H20: 0 | I20: 1
A21: Médias Diárias | B21: =AVERAGE(B2:B20) -> 9 | C21: =AVERAGE(C2:C20) -> 8.4210526 | D21: =AVERAGE(D2:D20) -> 1 | E21: =AVERAGE(E2:E20) -> 1.8947368 | F21: =AVERAGE(F2:F20) -> 2.5263158 | G21: =AVERAGE(G2:G20) -> 0 | H21: =AVERAGE(H2:H20) -> 1.0526316 | I21: =AVERAGE(I2:I20) -> 1.9473684
A22: Somatórias | B22: =SUM(B2:B20) -> 171 | C22: =SUM(C2:C20) -> 160 | D22: =SUM(D2:D20) -> 19 | E22: =SUM(E2:E20) -> 36 | F22: =SUM(F2:F20) -> 48 | G22: =SUM(G2:G20) -> 0 | H22: =SUM(H2:H20) -> 20 | I22: =SUM(I2:I20) -> 37
A23: Porcentagem | D23: =(D22*100)/C22 -> 11.875 | E23: =(E22*100)/C22 -> 22.5 | F23: =(F22*100)/C22 -> 30 | G23: =(G22*100)/C22 -> 0 | H23: =(H22*100)/C22 -> 12.5 | I23: =(I22*100)/C22 -> 23.125

Sheet Dez-23
A1: Data | B1: Created | C1: Resolved | D1: Everton | E1: Raphael | F1: Andre | G1: Não atribuídos | H1: Camille | I1: Jean
A2: sexta-feira, 1 de dezembro de 2023 | B2: 13 | C2: 14 | D2: 0 | E2: 6 | F2: 4 | G2: 0 | H2: 2 | I2: 2
A3: segunda-feira, 4 de dezembro de 2023 | B3: 13 | C3: 4 | D3: 1 | E3: 0 | F3: 2 | G3: 0 | H3: 0 | I3: 1
A4: terça-feira, 5 de dezembro de 2023 | B4: 15 | C4: 13 | D4: 2 | E4: 4 | F4: 3 | G4: 0 | H4: 2 | I4: 2
A5: quarta-feira, 6 de dezembro de 2023 | B5: 25 | C5: 15 | D5: 0 | E5: 1 | F5: 8 | G5: 0 | H5: 4 | I5: 2
A6: quinta-feira, 7 de dezembro de 2023 | B6: 10 | C6: 7 | D6: 2 | E6: 0 | F6: 1 | G6: 0 | H6: 2 | I6: 2
A7: sexta-feira, 8 de dezembro de 2023 | B7: 6 | C7: 14 | D7: 1 | E7: 0 | F7: 1 | G7: 0 | H7: 0 | I7: 12
A8: segunda-feira, 11 de dezembro de 2023 | B8: 11 | C8: 13 | D8: 2 | E8: 3 | F8: 2 | G8: 0 | H8: 5 | I8: 1
A9: terça-feira, 12 de dezembro de 2023 | B9: 6 | C9: 5 | D9: 0 | E9: 1 | F9: 0 | G9: 0 | H9: 3 | I9: 1
A10: quarta-feira, 13 de dezembro de 2023 | B10: 10 | C10: 8 | D10: 5 | E10: 0 | F10: 2 | G10: 0 | H10: 0 | I10: 1
A11: quinta-feira, 14 de dezembro de 2023 | B11: 9 | C11: 8 | D11: 0 | E11: 1 | F11: 3 | G11: 0 | H11: 1 | I11: 3
A12: sexta-feira, 15 de dezembro de 2023 | B12: 1 | C12: 11 | D12: 0 | E12: 6 | F12: 2 | G12: 0 | H12: 0 | I12: 3
A13: segunda-feira, 18 de dezembro de 2023 | B13: 13 | C13: 10 | D13: 2 | E13: 0 | F13: 1 | G13: 0 | H13: 6 | I13: 1
... A21: sexta-feira, 29 de dezembro de 2023 | B21: 4 | C21: 7 | D21: 0 | E21: 1 | F21: 2 | G21: 0 | H21: 1 | I21: 3
A22: Médias Diárias | B22: =AVERAGE(B2:B21) -> 10.3 | C22: =AVERAGE(C2:C21) -> 9.55 | D22: =AVERAGE(D2:D21) -> 1.1 | E22: =AVERAGE(E2:E21) -> 1.5 | F22: =AVERAGE(F2:F21) -> 2.85 | G22: =AVERAGE(G2:G21) -> 0 | H22: =AVERAGE(H2:H21) -> 1.9 | I22: =AVERAGE(I2:I21) -> 2.2
A23: Somatórias | B23: =SUM(B2:B21) -> 206 | C23: =SUM(C2:C21) -> 191 | D23: =SUM(D2:D21) -> 22 | E23: =SUM(E2:E21) -> 30 | F23: =SUM(F2:F21) -> 57 | G23: =SUM(G2:G21) -> 0 | H23: =SUM(H2:H21) -> 38 | I23: =SUM(I2:I21) -> 44
A24: Porcentagem | D24: =(D23*100)/C23 -> 11.518325 | E24: =(E23*100)/C23 -> 15.706806 | F24: =(F23*100)/C23 -> 29.842932 | G24: =(G23*100)/C23 -> 0 | H24: =(H23*100)/C23 -> 19.895288 | I24: =(I23*100)/C23 -> 23.036649
