Workbook

Sheet Resumo
A1: Médias Diárias
A2: Mês | B2: Criados | C2: Resolvidos | D2: Everton | E2: Raphael | F2: Andre | G2: Não atribuídos | H2: Camille | I2: Jean | J2: Reynaldo
A3: Janeiro | B3: =Jan!B30 -> 10.32 | C3: =Jan!C30 -> 9.8 | D3: =Jan!D30 -> 1.24 | E3: =Jan!E30 -> 0.92 | F3: =Jan!F30 -> 2.96 | G3: =Jan!G30 -> 0 | H3: =Jan!H30 -> 2.64 | I3: =Jan!I30 -> 2.04 | J3: =Jan!J30 -> 0
A4: Fevereiro | B4: =Fev!B30 -> 7.8695652 | C4: =Fev!C30 -> 7.5652174 | D4: =Fev!D30 -> 0.69565217 | E4: =Fev!E30 -> 1.2608696 | F4: =Fev!F30 -> 2.1304348 | G4: =Fev!G30 -> 0 | H4: =Fev!H30 -> 2.1304348 | I4: =Fev!I30 -> 1.3478261 | J4: =Fev!J30 -> 0
A5: Março | B5: =Mar!B30 -> 9.7727273 | C5: =Mar!C30 -> 10.409091 | D5: =Mar!D30 -> 1.5454545 | E5: =Mar!E30 -> 1.3636364 | F5: =Mar!F30 -> 2.6818182 | G5: =Mar!G30 -> 0 | H5: =Mar!H30 -> 2.6363636 | I5: =Mar!I30 -> 2.1818182 | J5: =Mar!J30 -> 0
A6: Abril | B6: =Abr!B30 -> 11.045455 | C6: =Abr!C30 -> 9.6363636 | D6: =Abr!D30 -> 1.4545455 | E6: =Abr!E30 -> 1.3636364 | F6: =Abr!F30 -> 2.5454545 | G6: =Abr!G30 -> 0 | H6: =Abr!H30 -> 2.3181818 | I6: =Abr!I30 -> 1.9545455 | J6: =Abr!J30 -> 0
A7: Maio | B7: =Mai!B30 -> 6.3333333 | C7: =Mai!C30 -> 6.9047619 | D7: =Mai!D30 -> 0.85714286 | E7: =Mai!E30 -> 1.047619 | F7: =Mai!F30 -> 2.7142857 | G7: =Mai!G30 -> 0 | H7: =Mai!H30 -> 0.80952381 | I7: =Mai!I30 -> 1.4761905 | J7: =Mai!J30 -> 0
A8: Junho | B8: =Jun!B30 -> 10.35 | C8: =Jun!C30 -> 9.85 | D8: =Jun!D30 -> 1.8 | E8: =Jun!E30 -> 1.15 | F8: =Jun!F30 -> 4 | G8: =Jun!G30 -> 0 | H8: =Jun!H30 -> 0.7 | I8: =Jun!I30 -> 2.2 | J8: =Jun!J30 -> 0
A9: Julho | B9: =Jul!B30 -> 9.2173913 | C9: =Jul!C30 -> 9.0434783 | D9: =Jul!D30 -> 2.2173913 | E9: =Jul!E30 -> 1.173913 | F9: =Jul!F30 -> 3.3043478 | G9: =Jul!G30 -> 0 | H9: =Jul!H30 -> 0.82608696 | I9: =Jul!I30 -> 1.4347826 | J9: =Jul!J30 -> 0.086956522
A10: Agosto | B10: =Ago!B30 -> 9.25 | C10: =Ago!C30 -> 9.5 | D10: =Ago!D30 -> 1.4583333 | E10: =Ago!E30 -> 1.2083333 | F10: =Ago!F30 -> 3.125 | G10: =Ago!G30 -> 0 | H10: =Ago!H30 -> 2 | I10: =Ago!I30 -> 1.7083333 | J10: =Ago!J30 -> 0
A11: Setembro | B11: =Set!B30 -> 7.9090909 | C11: =Set!C30 -> 8.2727273 | D11: =Set!D30 -> 0.95454545 | E11: =Set!E30 -> 1.3181818 | F11: =Set!F30 -> 3.8 | G11: =Set!G30 -> 0 | H11: =Set!H30 -> 0.72727273 | I11: =Set!I30 -> 3.5454545 | J11: =Set!J30 -> 0
A12: Outubro | B12: =Out!B30 -> 0 | C12: =Out!C30 -> 0 | D12: =Out!D30 -> 0 | E12: =Out!E30 -> 0 | F12: =Out!F30 -> 0 | G12: =Out!G30 -> 0 | H12: =Out!H30 -> 0 | I12: =Out!I30 -> 0 | J12: =Out!J30 -> 0
A13: Novembro | B13: =Nov!B30 -> 0 | C13: =Nov!C30 -> 0 | D13: =Nov!D30 -> 0 | E13: =Nov!E30 -> 0 | F13: =Nov!F30 -> 0 | G13: =Nov!G30 -> 0 | H13: =Nov!H30 -> 0 | I13: =Nov!I30 -> 0 | J13: =Nov!J30 -> 0
A14: Dezembro | B14: =Dez!B30 -> 0 | C14: =Dez!C30 -> 0 | D14: =Dez!D30 -> 0 | E14: =Dez!E30 -> 0 | F14: =Dez!F30 -> 0 | G14: =Dez!G30 -> 0 | H14: =Dez!H30 -> 0 | I14: =Dez!I30 -> 0 | J14: =Dez!J30 -> 0
A15: MÉDIA DIÁRIA | B15: =AVERAGE(B3:B11) -> 9.1186181 | C15: =AVERAGE(C3:C11) -> 8.9979599 | D15: =AVERAGE(D3:D11) -> 1.3581183 | E15: =AVERAGE(E3:E11) -> 1.2006877 | F15: =AVERAGE(F3:F11) -> 3.0290379 | G15: =AVERAGE(G3:G14) -> 0 | H15: =AVERAGE(H3:H11) -> 1.643096 | I15: =AVERAGE(I3:I11) -> 1.9876612 | J15: =AVERAGE(J3:J14) -> 0.0072463768
A18: Somatórias
A19: Mês | B19: Criados | C19: Resolvidos | D19: Everton | E19: Raphael | F19: Andre | G19: Não atribuídos | H19: Camille | I19: Jean | J19: Reynaldo
A20: Janeiro | B20: =Jan!B31 -> 258 | C20: =Jan!C31 -> 245 | D20: =Jan!D31 -> 31 | E20: =Jan!E31 -> 23 | F20: =Jan!F31 -> 74 | G20: =Jan!G31 -> 0 | H20: =Jan!H31 -> 66 | I20: =Jan!I31 -> 51 | J20: =Jan!J31 -> 0
A21: Fevereiro | B21: =Fev!B31 -> 181 | C21: =Fev!C31 -> 174 | D21: =Fev!D31 -> 16 | E21: =Fev!E31 -> 29 | F21: =Fev!F31 -> 49 | G21: =Fev!G31 -> 0 | H21: =Fev!H31 -> 49 | I21: =Fev!I31 -> 31 | J21: =Fev!J31 -> 0
A22: Março | B22: =Mar!B31 -> 215 | C22: =Mar!C31 -> 229 | D22: =Mar!D31 -> 34 | E22: =Mar!E31 -> 30 | F22: =Mar!F31 -> 59 | G22: =Mar!G31 -> 0 | H22: =Mar!H31 -> 58 | I22: =Mar!I31 -> 48 | J22: =Mar!J31 -> 0
A23: Abril | B23: =Abr!B31 -> 243 | C23: =Abr!C31 -> 212 | D23: =Abr!D31 -> 32 | E23: =Abr!E31 -> 30 | F23: =Abr!F31 -> 56 | G23: =Abr!G31 -> 0 | H23: =Abr!H31 -> 51 | I23: =Abr!I31 -> 43 | J23: =Abr!J31 -> 0
A24: Maio | B24: =Mai!B31 -> 133 | C24: =Mai!C31 -> 145 | D24: =Mai!D31 -> 18 | E24: =Mai!E31 -> 22 | F24: =Mai!F31 -> 57 | G24: =Mai!G31 -> 0 | H24: =Mai!H31 -> 17 | I24: =Mai!I31 -> 31 | J24: =Mai!J31 -> 0
A25: Junho | B25: =Jun!B31 -> 207 | C25: =Jun!C31 -> 197 | D25: =Jun!D31 -> 36 | E25: =Jun!E31 -> 23 | F25: =Jun!F31 -> 80 | G25: =Jun!G31 -> 0 | H25: =Jun!H31 -> 14 | I25: =Jun!I31 -> 44 | J25: =Jun!J31 -> 0
A26: Julho | B26: =Jul!B31 -> 212 | C26: =Jul!C31 -> 208 | D26: =Jul!D31 -> 51 | E26: =Jul!E31 -> 27 | F26: =Jul!F31 -> 76 | G26: =Jul!G31 -> 0 | H26: =Jul!H31 -> 19 | I26: =Jul!I31 -> 33 | J26: =Jul!J31 -> 2
A27: Agosto | B27: =Ago!B31 -> 222 | C27: =Ago!C31 -> 228 | D27: =Ago!D31 -> 35 | E27: =Ago!E31 -> 29 | F27: =Ago!F31 -> 75 | G27: =Ago!G31 -> 0 | H27: =Ago!H31 -> 48 | I27: =Ago!I31 -> 41 | J27: =Ago!J31 -> 0
A28: Setembro | B28: =Set!B31 -> 174 | C28: =Set!C31 -> 182 | D28: =Set!D31 -> 21 | E28: =Set!E31 -> 29 | F28: =Set!F31 -> 38 | G28: =Set!G31 -> 0 | H28: =Set!H31 -> 16 | I28: =Set!I31 -> 78 | J28: =Set!J31 -> 0
A29: Outubro | B29: =Out!B31 -> 0 | C29: =Out!C31 -> 0 | D29: =Out!D31 -> 0 | E29: =Out!E31 -> 0 | F29: =Out!F31 -> 0 | G29: =Out!G31 -> 0 | H29: =Out!H31 -> 0 | I29: =Out!I31 -> 0 | J29: =Out!J31 -> 0
A30: Novembro | B30: =Nov!B31 -> 0 | C30: =Nov!C31 -> 0 | D30: =Nov!D31 -> 0 | E30: =Nov!E31 -> 0 | F30: =Nov!F31 -> 0 | G30: =Nov!G31 -> 0 | H30: =Nov!H31 -> 0 | I30: =Nov!I31 -> 0 | J30: =Nov!J31 -> 0
A31: Dezembro | B31: =Dez!B31 -> 0 | C31: =Dez!C31 -> 0 | D31: =Dez!D31 -> 0 | E31: =Dez!E31 -> 0 | F31: =Dez!F31 -> 0 | G31: =Dez!G31 -> 0 | H31: =Dez!H31 -> 0 | I31: =Dez!I31 -> 0 | J31: =Dez!J31 -> 0
A32: TOTAL NO ANO | B32: =SUM(B20:B31) -> 1845 | C32: =SUM(C20:C31) -> 1820 | D32: =SUM(D20:D31) -> 274 | E32: =SUM(E20:E31) -> 242 | F32: =SUM(F20:F31) -> 564 | G32: =SUM(G20:G31) -> 0 | H32: =SUM(H20:H31) -> 338 | I32: =SUM(I20:I31) -> 400 | J32: =SUM(J20:J31) -> 2
A33: MÉDIA MENSAL | B33: =AVERAGE(B20:B28) -> 205 | C33: =AVERAGE(C20:C28) -> 202.22222 | D33: =AVERAGE(D20:D28) -> 30.444444 | E33: =AVERAGE(E20:E28) -> 26.888889 | F33: =AVERAGE(F20:F28) -> 62.666667 | G33: =AVERAGE(G20:G31) -> 0 | H33: =AVERAGE(H20:H28) -> 37.555556 | I33: =AVERAGE(I20:I28) -> 44.444444 | J33: =AVERAGE(J20:J31) -> 0.16666667
A36: Porcentagem
A37: Mês | B37: Everton | C37: Raphael | D37: Andre | E37: Não atribuídos | F37: Camille | G37: Jean | H37: Reynaldo | I37: TOTAL
A38: Janeiro | B38: =Jan!D32 -> 0.12653061 | C38: =Jan!E32 -> 0.093877551 | D38: =Jan!F32 -> 0.30204082 | E38: =Jan!G32 -> 0 | F38: =Jan!H32 -> 0.26938776 | G38: =Jan!I32 -> 0.20816327 | H38: =Jan!J32 -> 0 | I38: =SUM(B38:H38) -> 1
A39: Fevereiro | B39: =Fev!D32 -> 0.091954023 | C39: =Fev!E32 -> 0.16666667 | D39: =Fev!F32 -> 0.2816092 | E39: =Fev!G32 -> 0 | F39: =Fev!H32 -> 0.2816092 | G39: =Fev!I32 -> 0.17816092 | H39: =Fev!J32 -> 0 | I39: =SUM(B39:H39) -> 1
A40: Março | B40: =Mar!D32 -> 0.14847162 | C40: =Mar!E32 -> 0.13100437 | D40: =Mar!F32 -> 0.25764192 | E40: =Mar!G32 -> 0 | F40: =Mar!H32 -> 0.25327511 | G40: =Mar!I32 -> 0.20960699 | H40: =Mar!J32 -> 0 | I40: =SUM(B40:H40) -> 1
A41: Abril | B41: =Abr!D32 -> 0.1509434 | C41: =Abr!E32 -> 0.14150943 | D41: =Abr!F32 -> 0.26415094 | E41: =Abr!G32 -> 0 | F41: =Abr!H32 -> 0.24056604 | G41: =Abr!I32 -> 0.20283019 | H41: =Abr!J32 -> 0 | I41: =SUM(B41:H41) -> 1
A42: Maio | B42: =Mai!D32 -> 0.12413793 | C42: =Mai!E32 -> 0.15172414 | D42: =Mai!F32 -> 0.39310345 | E42: =Mai!G32 -> 0 | F42: =Mai!H32 -> 0.11724138 | G42: =Mai!I32 -> 0.2137931 | H42: =Mai!J32 -> 0 | I42: =SUM(B42:H42) -> 1
A43: Junho | B43: =Jun!D32 -> 0.18274112 | C43: =Jun!E32 -> 0.11675127 | D43: =Jun!F32 -> 0.40609137 | E43: =Jun!G32 -> 0 | F43: =Jun!H32 -> 0.07106599 | G43: =Jun!I32 -> 0.22335025 | H43: =Jun!J32 -> 0 | I43: =SUM(B43:H43) -> 1
A44: Julho | B44: =Jul!D32 -> 0.24519231 | C44: =Jul!E32 -> 0.12980769 | D44: =Jul!F32 -> 0.36538462 | E44: =Jul!G32 -> 0 | F44: =Jul!H32 -> 0.091346154 | G44: =Jul!I32 -> 0.15865385 | H44: =Jul!J32 -> 0.0096153846 | I44: =SUM(B44:H44) -> 1
...

Sheet Jan
A1: Data | B1: Created | C1: Resolved | D1: Everton | E1: Raphael | F1: Andre | G1: Não atribuídos | H1: Camille | I1: Jean
A2: terça-feira, 2 de janeiro de 2024 | B2: 29 | C2: 6 | D2: 1 | E2: 1 | F2: 1 | G2: 0 | H2: 2 | I2: 1
A3: quarta-feira, 3 de janeiro de 2024 | B3: 7 | C3: 29 | D3: 2 | E3: 1 | F3: 11 | G3: 0 | H3: 12 | I3: 3
A4: quinta-feira, 4 de janeiro de 2024 | B4: 14 | C4: 21 | D4: 1 | E4: 8 | F4: 3 | G4: 0 | H4: 0 | I4: 9
A5: sexta-feira, 5 de janeiro de 2024 | B5: 25 | C5: 9 | D5: 2 | E5: 2 | F5: 2 | G5: 0 | H5: 0 | I5: 3
A6: segunda-feira, 8 de janeiro de 2024 | B6: 11 | C6: 24 | D6: 3 | E6: 0 | F6: 4 | G6: 0 | H6: 17 | I6: 0
A7: terça-feira, 9 de janeiro de 2024 | B7: 5 | C7: 8 | D7: 3 | E7: 0 | F7: 3 | G7: 0 | H7: 1 | I7: 1
A8: quarta-feira, 10 de janeiro de 2024 | B8: 9 | C8: 6 | D8: 0 | E8: 0 | F8: 2 | G8: 0 | H8: 1 | I8: 3
A9: quinta-feira, 11 de janeiro de 2024 | B9: 11 | C9: 11 | D9: 4 | E9: 0 | F9: 3 | G9: 0 | H9: 0 | I9: 4
A10: sexta-feira, 12 de janeiro de 2024 | B10: 5 | C10: 9 | D10: 0 | E10: 0 | F10: 1 | G10: 0 | H10: 7 | I10: 1
A11: sábado, 13 de janeiro de 2024 | B11: 1 | C11: 2 | D11: 2 | E11: 0 | F11: 0 | G11: 0 | H11: 0 | I11: 0
A12: domingo, 14 de janeiro de 2024 | B12: 1 | C12: 1 | D12: 0 | E12: 0 | F12: 0 | G12: 0 | H12: 0 | I12: 1
A13: segunda-feira, 15 de janeiro de 2024 | B13: 7 | C13: 6 | D13: 2 | E13: 0 | F13: 3 | G13: 0 | H13: 0 | I13: 1
... A26: quarta-feira, 31 de janeiro de 2024 | B26: 16 | C26: 8 | D26: 0 | E26: 2 | F26: 6 | G26: 0 | H26: 0 | I26: 0
A30: Médias Diárias | B30: =AVERAGE(B2:B29) -> 10.32 | C30: =AVERAGE(C2:C29) -> 9.8 | D30: =AVERAGE(D2:D29) -> 1.24 | E30: =AVERAGE(E2:E29) -> 0.92 | F30: =AVERAGE(F2:F29) -> 2.96 | G30: =AVERAGE(G2:G29) -> 0 | H30: =AVERAGE(H2:H29) -> 2.64 | I30: =AVERAGE(I2:I29) -> 2.04
A31: Somatórias | B31: =SUM(B2:B29) -> 258 | C31: =SUM(C2:C29) -> 245 | D31: =SUM(D2:D29) -> 31 | E31: =SUM(E2:E29) -> 23 | F31: =SUM(F2:F29) -> 74 | G31: =SUM(G2:G29) -> 0 | H31: =SUM(H2:H29) -> 66 | I31: =SUM(I2:I29) -> 51
A32: Porcentagem | D32: =D31/C31 -> 0.12653061 | E32: =E31/C31 -> 0.093877551 | F32: =F31/C31 -> 0.30204082 | G32: =G31/C31 -> 0 | H32: =H31/C31 -> 0.26938776 | I32: =I31/C31 -> 0.20816327

Sheet Fev
A1: Data | B1: Created | C1: Resolved | D1: Everton | E1: Raphael | F1: Andre | G1: Não atribuídos | H1: Camille | I1: Jean
A2: quinta-feira, 1 de fevereiro de 2024 | B2: 9 | C2: 9 | D2: 0 | E2: 5 | F2: 2 | G2: 0 | H2: 0 | I2: 2
A3: sexta-feira, 2 de fevereiro de 2024 | B3: 15 | C3: 9 | D3: 0 | E3: 0 | F3: 3 | G3: 0 | H3: 3 | I3: 3
A4: sábado, 3 de fevereiro de 2024 | B4: 3 | C4: 1 | D4: 0 | E4: 0 | F4: 1 | G4: 0 | H4: 0 | I4: 0
A5: domingo, 4 de fevereiro de 2024 | B5: 0 | C5: 1 | D5: 0 | E5: 1 | F5: 0 | G5: 0 | H5: 0 | I5: 0
A6: segunda-feira, 5 de fevereiro de 2024 | B6: 9 | C6: 11 | D6: 1 | E6: 3 | F6: 3 | G6: 0 | H6: 0 | I6: 4
A7: terça-feira, 6 de fevereiro de 2024 | B7: 18 | C7: 11 | D7: 0 | E7: 0 | F7: 4 | G7: 0 | H7: 2 | I7: 5
A8: quarta-feira, 7 de fevereiro de 2024 | B8: 15 | C8: 3 | D8: 0 | E8: 0 | F8: 2 | G8: 0 | H8: 1 | I8: 0
A9: quinta-feira, 8 de fevereiro de 2024 | B9: 4 | C9: 6 | D9: 0 | E9: 3 | F9: 2 | G9: 0 | H9: 1 | I9: 0
A10: sexta-feira, 9 de fevereiro de 2024 | B10: 11 | C10: 13 | D10: 0 | E10: 5 | F10: 6 | G10: 0 | H10: 0 | I10: 2
A11: segunda-feira, 12 de fevereiro de 2024 | B11: 0 | C11: 0 | D11: 0 | E11: 0 | F11: 0 | G11: 0 | H11: 0 | I11: 0
A12: terça-feira, 13 de fevereiro de 2024 | B12: 0 | C12: 0 | D12: 0 | E12: 0 | F12: 0 | G12: 0 | H12: 0 | I12: 0
A13: quarta-feira, 14 de fevereiro de 2024 | B13: 4 | C13: 6 | D13: 0 | E13: 0 | F13: 2 | G13: 0 | H13: 1 | I13: 3
... A24: quinta-feira, 29 de fevereiro de 2024 | B24: 6 | C24: 6 | D24: 0 | E24: 0 | F24: 3 | G24: 0 | H24: 0 | I24: 3
A30: Médias Diárias | B30: =AVERAGE(B2:B29) -> 7.8695652 | C30: =AVERAGE(C2:C29) -> 7.5652174 | D30: =AVERAGE(D2:D29) -> 0.69565217 | E30: =AVERAGE(E2:E29) -> 1.2608696 | F30: =AVERAGE(F2:F29) -> 2.1304348 | G30: =AVERAGE(G2:G29) -> 0 | H30: =AVERAGE(H2:H29) -> 2.1304348 | I30: =AVERAGE(I2:I29) -> 1.3478261
A31: Somatórias | B31: =SUM(B2:B29) -> 181 | C31: =SUM(C2:C29) -> 174 | D31: =SUM(D2:D29) -> 16 | E31: =SUM(E2:E29) -> 29 | F31: =SUM(F2:F29) -> 49 | G31: =SUM(G2:G29) -> 0 | H31: =SUM(H2:H29) -> 49 | I31: =SUM(I2:I29) -> 31
A32: Porcentagem | D32: =D31/C31 -> 0.091954023 | E32: =E31/C31 -> 0.16666667 | F32: =F31/C31 -> 0.2816092 | G32: =G31/C31 -> 0 | H32: =H31/C31 -> 0.2816092 | I32: =I31/C31 -> 0.17816092

Sheet Mar
A1: Data | B1: Created | C1: Resolved | D1: Everton | E1: Raphael | F1: Andre | G1: Não atribuídos | H1: Camille | I1: Jean
A2: sexta-feira, 1 de março de 2024 | B2: 12 | C2: 7 | D2: 2 | E2: 2 | F2: 0 | G2: 0 | H2: 3 | I2: 0
A3: segunda-feira, 4 de março de 2024 | B3: 33 | C3: 11 | D3: 1 | E3: 2 | F3: 1 | G3: 0 | H3: 0 | I3: 7
A4: terça-feira, 5 de março de 2024 | B4: 9 | C4: 20 | D4: 1 | E4: 3 | F4: 10 | G4: 0 | H4: 1 | I4: 5
A5: quarta-feira, 6 de março de 2024 | B5: 3 | C5: 10 | D5: 6 | E5: 0 | F5: 2 | G5: 0 | H5: 1 | I5: 1
A6: quinta-feira, 7 de março de 2024 | B6: 8 | C6: 24 | D6: 1 | E6: 5 | F6: 1 | G6: 0 | H6: 17 | I6: 0
A7: sexta-feira, 8 de março de 2024 | B7: 9 | C7: 9 | D7: 2 | E7: 2 | F7: 1 | G7: 0 | H7: 3 | I7: 1
A8: sábado, 9 de março de 2024 | B8: 0 | C8: 1 | D8: 1 | E8: 0 | F8: 0 | G8: 0 | H8: 0 | I8: 0
A9: segunda-feira, 11 de março de 2024 | B9: 8 | C9: 5 | D9: 2 | E9: 0 | F9: 2 | G9: 0 | H9: 0 | I9: 1
A10: terça-feira, 12 de março de 2024 | B10: 12 | C10: 5 | D10: 0 | E10: 2 | F10: 2 | G10: 0 | H10: 0 | I10: 1
A11: quarta-feira, 13 de março de 2024 | B11: 10 | C11: 13 | D11: 2 | E11: 2 | F11: 7 | G11: 0 | H11: 0 | I11: 2
A12: quinta-feira, 14 de março de 2024 | B12: 10 | C12: 11 | D12: 3 | E12: 0 | F12: 3 | G12: 0 | H12: 1 | I12: 4
A13: sexta-feira, 15 de março de 2024 | B13: 6 | C13: 10 | D13: 3 | E13: 1 | F13: 4 | G13: 0 | H13: 1 | I13: 1
... A23: sexta-feira, 29 de março de 2024 | B23: 0 | C23: 0 | D23: 0 | E23: 0 | F23: 0 | G23: 0 | H23: 0 | I23: 0
A30: Médias Diárias | B30: =AVERAGE(B2:B29) -> 9.7727273 | C30: =AVERAGE(C2:C29) -> 10.409091 | D30: =AVERAGE(D2:D29) -> 1.5454545 | E30: =AVERAGE(E2:E29) -> 1.3636364 | F30: =AVERAGE(F2:F29) -> 2.6818182 | G30: =AVERAGE(G2:G29) -> 0 | H30: =AVERAGE(H2:H29) -> 2.6363636 | I30: =AVERAGE(I2:I29) -> 2.1818182
A31: Somatórias | B31: =SUM(B2:B29) -> 215 | C31: =SUM(C2:C29) -> 229 | D31: =SUM(D2:D29) -> 34 | E31: =SUM(E2:E29) -> 30 | F31: =SUM(F2:F29) -> 59 | G31: =SUM(G2:G29) -> 0 | H31: =SUM(H2:H29) -> 58 | I31: =SUM(I2:I29) -> 48
A32: Porcentagem | D32: =D31/C31 -> 0.14847162 | E32: =E31/C31 -> 0.13100437 | F32: =F31/C31 -> 0.25764192 | G32: =G31/C31 -> 0 | H32: =H31/C31 -> 0.25327511 | I32: =I31/C31 -> 0.20960699

Sheet Abr
A1: Data | B1: Created | C1: Resolved | D1: Everton | E1: Raphael | F1: Andre | G1: Não atribuídos | H1: Camille | I1: Jean
A2: segunda-feira, 1 de abril de 2024 | B2: 11 | C2: 2 | D2: 0 | E2: 0 | F2: 1 | G2: 0 | H2: 0 | I2: 1
A3: terça-feira, 2 de abril de 2024 | B3: 6 | C3: 6 | D3: 0 | E3: 2 | F3: 2 | G3: 0 | H3: 0 | I3: 2
A4: quarta-feira, 3 de abril de 2024 | B4: 14 | C4: 11 | D4: 1 | E4: 1 | F4: 2 | G4: 0 | H4: 5 | I4: 2
A5: quinta-feira, 4 de abril de 2024 | B5: 9 | C5: 9 | D5: 0 | E5: 6 | F5: 1 | G5: 0 | H5: 1 | I5: 1
A6: sexta-feira, 5 de abril de 2024 | B6: 10 | C6: 13 | D6: 5 | E6: 0 | F6: 2 | G6: 0 | H6: 2 | I6: 4
A7: segunda-feira, 8 de abril de 2024 | B7: 8 | C7: 6 | D7: 1 | E7: 1 | F7: 2 | G7: 0 | H7: 0 | I7: 2
A8: terça-feira, 9 de abril de 2024 | B8: 19 | C8: 15 | D8: 2 | E8: 3 | F8: 5 | G8: 0 | H8: 2 | I8: 3
A9: quarta-feira, 10 de abril de 2024 | B9: 9 | C9: 11 | D9: 2 | E9: 2 | F9: 5 | G9: 0 | H9: 0 | I9: 2
A10: quinta-feira, 11 de abril de 2024 | B10: 7 | C10: 9 | D10: 1 | E10: 3 | F10: 4 | G10: 0 | H10: 1 | I10: 0
A11: sexta-feira, 12 de abril de 2024 | B11: 4 | C11: 3 | D11: 0 | E11: 1 | F11: 2 | G11: 0 | H11: 0 | I11: 0
A12: segunda-feira, 15 de abril de 2024 | B12: 9 | C12: 3 | D12: 1 | E12: 0 | F12: 1 | G12: 0 | H12: 0 | I12: 1
A13: terça-feira, 16 de abril de 2024 | B13: 9 | C13: 9 | D13: 1 | E13: 2 | F13: 2 | G13: 0 | H13: 3 | I13: 1
... A23: terça-feira, 30 de abril de 2024 | B23: 11 | C23: 9 | D23: 2 | E23: 1 | F23: 5 | G23: 0 | H23: 1 | I23: 0
A30: Médias Diárias | B30: =AVERAGE(B2:B29) -> 11.045455 | C30: =AVERAGE(C2:C29) -> 9.6363636 | D30: =AVERAGE(D2:D29) -> 1.4545455 | E30: =AVERAGE(E2:E29) -> 1.3636364 | F30: =AVERAGE(F2:F29) -> 2.5454545 | G30: =AVERAGE(G2:G29) -> 0 | H30: =AVERAGE(H2:H29) -> 2.3181818 | I30: =AVERAGE(I2:I29) -> 1.9545455
A31: Somatórias | B31: =SUM(B2:B29) -> 243 | C31: =SUM(C2:C29) -> 212 | D31: =SUM(D2:D29) -> 32 | E31: =SUM(E2:E29) -> 30 | F31: =SUM(F2:F29) -> 56 | G31: =SUM(G2:G29) -> 0 | H31: =SUM(H2:H29) -> 51 | I31: =SUM(I2:I29) -> 43
A32: Porcentagem | D32: =D31/C31 -> 0.1509434 | E32: =E31/C31 -> 0.14150943 | F32: =F31/C31 -> 0.26415094 | G32: =G31/C31 -> 0 | H32: =H31/C31 -> 0.24056604 | I32: =I31/C31 -> 0.20283019

Sheet Mai
A1: Data | B1: Created | C1: Resolved | D1: Everton | E1: Raphael | F1: Andre | G1: Não atribuídos | H1: Camille | I1: Jean
A2: quinta-feira, 2 de maio de 2024 | B2: 12 | C2: 12 | D2: 0 | E2: 2 | F2: 7 | G2: 0 | H2: 1 | I2: 2
A3: sexta-feira, 3 de maio de 2024 | B3: 8 | C3: 3 | D3: 0 | E3: 0 | F3: 3 | G3: 0 | H3: 0 | I3: 0
A4: segunda-feira, 6 de maio de 2024 | B4: 11 | C4: 16 | D4: 7 | E4: 1 | F4: 5 | G4: 0 | H4: 0 | I4: 3
A5: terça-feira, 7 de maio de 2024 | B5: 6 | C5: 6 | D5: 1 | E5: 3 | F5: 0 | G5: 0 | H5: 0 | I5: 2
A6: quarta-feira, 8 de maio de 2024 | B6: 4 | C6: 11 | D6: 1 | E6: 7 | F6: 2 | G6: 0 | H6: 0 | I6: 1
A7: quinta-feira, 9 de maio de 2024 | B7: 1 | C7: 3 | D7: 0 | E7: 1 | F7: 0 | G7: 0 | H7: 0 | I7: 2
A8: sexta-feira, 10 de maio de 2024 | B8: 6 | C8: 6 | D8: 1 | E8: 1 | F8: 3 | G8: 0 | H8: 0 | I8: 1
A9: segunda-feira, 13 de maio de 2024 | B9: 3 | C9: 5 | D9: 0 | E9: 2 | F9: 1 | G9: 0 | H9: 0 | I9: 2
A10: terça-feira, 14 de maio de 2024 | B10: 11 | C10: 9 | D10: 4 | E10: 0 | F10: 2 | G10: 0 | H10: 0 | I10: 3
A11: quarta-feira, 15 de maio de 2024 | B11: 5 | C11: 7 | D11: 0 | E11: 0 | F11: 5 | G11: 0 | H11: 1 | I11: 1
A12: quinta-feira, 16 de maio de 2024 | B12: 1 | C12: 16 | D12: 0 | E12: 0 | F12: 1 | G12: 0 | H12: 15 | I12: 0
A13: sexta-feira, 17 de maio de 2024 | B13: 18 | C13: 3 | D13: 2 | E13: 0 | F13: 1 | G13: 0 | H13: 0 | I13: 0
... A22: sexta-feira, 31 de maio de 2024 | B22: 9 | C22: 7 | D22: 0 | E22: 1 | F22: 4 | G22: 0 | H22: 0 | I22: 2
A30: Médias Diárias | B30: =AVERAGE(B2:B29) -> 6.3333333 | C30: =AVERAGE(C2:C29) -> 6.9047619 | D30: =AVERAGE(D2:D29) -> 0.85714286 | E30: =AVERAGE(E2:E29) -> 1.047619 | F30: =AVERAGE(F2:F29) -> 2.7142857 | G30: =AVERAGE(G2:G29) -> 0 | H30: =AVERAGE(H2:H29) -> 0.80952381 | I30: =AVERAGE(I2:I29) -> 1.4761905
A31: Somatórias | B31: =SUM(B2:B29) -> 133 | C31: =SUM(C2:C29) -> 145 | D31: =SUM(D2:D29) -> 18 | E31: =SUM(E2:E29) -> 22 | F31: =SUM(F2:F29) -> 57 | G31: =SUM(G2:G29) -> 0 | H31: =SUM(H2:H29) -> 17 | I31: =SUM(I2:I29) -> 31
A32: Porcentagem | D32: =D31/C31 -> 0.12413793 | E32: =E31/C31 -> 0.15172414 | F32: =F31/C31 -> 0.39310345 | G32: =G31/C31 -> 0 | H32: =H31/C31 -> 0.11724138 | I32: =I31/C31 -> 0.2137931

Sheet Jun
A1: Data | B1: Created | C1: Resolved | D1: Everton | E1: Raphael | F1: Andre | G1: Não atribuídos | H1: Camille | I1: Jean
A2: segunda-feira, 3 de junho de 2024 | B2: 26 | C2: 17 | D2: 1 | E2: 1 | F2: 12 | G2: 0 | H2: 0 | I2: 3
A3: terça-feira, 4 de junho de 2024 | B3: 16 | C3: 20 | D3: 0 | E3: 1 | F3: 8 | G3: 0 | H3: 2 | I3: 9
A4: quarta-feira, 5 de junho de 2024 | B4: 9 | C4: 5 | D4: 1 | E4: 0 | F4: 3 | G4: 0 | H4: 0 | I4: 1
A5: quinta-feira, 6 de junho de 2024 | B5: 11 | C5: 9 | D5: 5 | E5: 2 | F5: 1 | G5: 0 | H5: 0 | I5: 1
A6: sexta-feira, 7 de junho de 2024 | B6: 3 | C6: 4 | D6: 3 | E6: 0 | F6: 1 | G6: 0 | H6: 0 | I6: 0
A7: segunda-feira, 10 de junho de 2024 | B7: 8 | C7: 14 | D7: 3 | E7: 0 | F7: 3 | G7: 0 | H7: 8 | I7: 0
A8: terça-feira, 11 de junho de 2024 | B8: 2 | C8: 12 | D8: 3 | E8: 7 | F8: 1 | G8: 0 | H8: 0 | I8: 1
A9: quarta-feira, 12 de junho de 2024 | B9: 9 | C9: 6 | D9: 3 | E9: 0 | F9: 1 | G9: 0 | H9: 1 | I9: 1
A10: quinta-feira, 13 de junho de 2024 | B10: 3 | C10: 3 | D10: 1 | E10: 0 | F10: 1 | G10: 0 | H10: 0 | I10: 1
A11: sexta-feira, 14 de junho de 2024 | B11: 6 | C11: 6 | D11: 1 | E11: 0 | F11: 3 | G11: 0 | H11: 0 | I11: 2
A12: segunda-feira, 17 de junho de 2024 | B12: 6 | C12: 10 | D12: 1 | E12: 2 | F12: 6 | G12: 0 | H12: 0 | I12: 1
A13: terça-feira, 18 de junho de 2024 | B13: 21 | C13: 13 | D13: 0 | E13: 2 | F13: 9 | G13: 0 | H13: 0 | I13: 2
... A21: sexta-feira, 28 de junho de 2024 | B21: 9 | C21: 3 | D21: 1 | E21: 0 | F21: 2 | G21: 0 | H21: 0 | I21: 0
A30: Médias Diárias | B30: =AVERAGE(B2:B29) -> 10.35 | C30: =AVERAGE(C2:C29) -> 9.85 | D30: =AVERAGE(D2:D29) -> 1.8 | E30: =AVERAGE(E2:E29) -> 1.15 | F30: =AVERAGE(F2:F29) -> 4 | G30: =AVERAGE(G2:G29) -> 0 | H30: =AVERAGE(H2:H29) -> 0.7 | I30: =AVERAGE(I2:I29) -> 2.2
A31: Somatórias | B31: =SUM(B2:B29) -> 207 | C31: =SUM(C2:C29) -> 197 | D31: =SUM(D2:D29) -> 36 | E31: =SUM(E2:E29) -> 23 | F31: =SUM(F2:F29) -> 80 | G31: =SUM(G2:G29) -> 0 | H31: =SUM(H2:H29) -> 14 | I31: =SUM(I2:I29) -> 44
A32: Porcentagem | D32: =D31/C31 -> 0.18274112 | E32: =E31/C31 -> 0.11675127 | F32: =F31/C31 -> 0.40609137 | G32: =G31/C31 -> 0 | H32: =H31/C31 -> 0.07106599 | I32: =I31/C31 -> 0.22335025

Sheet Jul
A1: Data | B1: Created | C1: Resolved | D1: Everton | E1: Raphael | F1: Andre | G1: Não atribuídos | H1: Camille | I1: Jean | J1: Reynaldo
A2: segunda-feira, 1 de julho de 2024 | B2: 10 | C2: 12 | D2: 6 | E2: 0 | F2: 5 | G2: 0 | H2: 0 | I2: 1 | J2: 0
A3: terça-feira, 2 de julho de 2024 | B3: 9 | C3: 6 | D3: 0 | E3: 1 | F3: 4 | G3: 0 | H3: 0 | I3: 1 | J3: 0
A4: quarta-feira, 3 de julho de 2024 | B4: 8 | C4: 6 | D4: 3 | E4: 2 | F4: 1 | G4: 0 | H4: 0 | I4: 0 | J4: 0
A5: quinta-feira, 4 de julho de 2024 | B5: 6 | C5: 5 | D5: 1 | E5: 1 | F5: 2 | G5: 0 | H5: 0 | I5: 1 | J5: 0
A6: sexta-feira, 5 de julho de 2024 | B6: 5 | C6: 14 | D6: 3 | E6: 7 | F6: 2 | G6: 0 | H6: 1 | I6: 1 | J6: 0
A7: segunda-feira, 8 de julho de 2024 | B7: 3 | C7: 3 | D7: 2 | E7: 1 | F7: 0 | G7: 0 | H7: 0 | I7: 0 | J7: 0
A8: terça-feira, 9 de julho de 2024 | B8: 0 | C8: 0 | D8: 0 | E8: 0 | F8: 0 | G8: 0 | H8: 0 | I8: 0 | J8: 0
A9: quarta-feira, 10 de julho de 2024 | B9: 17 | C9: 19 | D9: 0 | E9: 0 | F9: 6 | G9: 0 | H9: 12 | I9: 1 | J9: 0
A10: quinta-feira, 11 de julho de 2024 | B10: 9 | C10: 10 | D10: 4 | E10: 0 | F10: 2 | G10: 0 | H10: 0 | I10: 4 | J10: 0
A11: sexta-feira, 12 de julho de 2024 | B11: 22 | C11: 9 | D11: 1 | E11: 2 | F11: 5 | G11: 0 | H11: 1 | I11: 0 | J11: 0
A12: segunda-feira, 15 de julho de 2024 | B12: 13 | C12: 16 | D12: 1 | E12: 1 | F12: 5 | G12: 0 | H12: 0 | I12: 9 | J12: 0
A13: terça-feira, 16 de julho de 2024 | B13: 5 | C13: 18 | D13: 3 | E13: 0 | F13: 14 | G13: 0 | H13: 0 | I13: 1 | J13: 0
... A24: quarta-feira, 31 de julho de 2024 | B24: 8 | C24: 8 | D24: 2 | E24: 0 | F24: 3 | G24: 0 | H24: 1 | I24: 2 | J24: 0
A30: Médias Diárias | B30: =AVERAGE(B2:B29) -> 9.2173913 | C30: =AVERAGE(C2:C29) -> 9.0434783 | D30: =AVERAGE(D2:D29) -> 2.2173913 | E30: =AVERAGE(E2:E29) -> 1.173913 | F30: =AVERAGE(F2:F29) -> 3.3043478 | G30: =AVERAGE(G2:G29) -> 0 | H30: =AVERAGE(H2:H29) -> 0.82608696 | I30: =AVERAGE(I2:I29) -> 1.4347826 | J30: =AVERAGE(J2:J29) -> 0.086956522
A31: Somatórias | B31: =SUM(B2:B29) -> 212 | C31: =SUM(C2:C29) -> 208 | D31: =SUM(D2:D29) -> 51 | E31: =SUM(E2:E29) -> 27 | F31: =SUM(F2:F29) -> 76 | G31: =SUM(G2:G29) -> 0 | H31: =SUM(H2:H29) -> 19 | I31: =SUM(I2:I29) -> 33 | J31: =SUM(J2:J29) -> 2
A32: Porcentagem | D32: =D31/C31 -> 0.24519231 | E32: =E31/C31 -> 0.12980769 | F32: =F31/C31 -> 0.36538462 | G32: =G31/C31 -> 0 | H32: =H31/C31 -> 0.091346154 | I32: =I31/C31 -> 0.15865385 | J32: =J31/C31 -> 0.0096153846

Sheet Ago
A1: Data | B1: Created | C1: Resolved | D1: Everton | E1: Raphael | F1: Andre | G1: Não atribuídos | H1: Camille | I1: Jean | J1: Reynaldo
A2: quinta-feira, 1 de agosto de 2024 | B2: 9 | C2: 6 | D2: 1 | E2: 1 | F2: 2 | G2: 0 | H2: 0 | I2: 2 | J2: 0
A3: sexta-feira, 2 de agosto de 2024 | B3: 8 | C3: 34 | D3: 2 | E3: 2 | F3: 3 | G3: 0 | H3: 26 | I3: 1 | J3: 0
A4: sábado, 3 de agosto de 2024 | B4: 0 | C4: 1 | D4: 0 | E4: 1 | F4: 0 | G4: 0 | H4: 0 | I4: 0 | J4: 0
A5: segunda-feira, 5 de agosto de 2024 | B5: 12 | C5: 5 | D5: 2 | E5: 0 | F5: 0 | G5: 0 | H5: 1 | I5: 2 | J5: 0
A6: terça-feira, 6 de agosto de 2024 | B6: 9 | C6: 8 | D6: 2 | E6: 0 | F6: 2 | G6: 0 | H6: 0 | I6: 4 | J6: 0
A7: quarta-feira, 7 de agosto de 2024 | B7: 5 | C7: 3 | D7: 1 | E7: 0 | F7: 1 | G7: 0 | H7: 1 | I7: 0 | J7: 0
A8: quinta-feira, 8 de agosto de 2024 | B8: 23 | C8: 4 | D8: 0 | E8: 2 | F8: 0 | G8: 0 | H8: 1 | I8: 1 | J8: 0
A9: sexta-feira, 9 de agosto de 2024 | B9: 9 | C9: 10 | D9: 1 | E9: 1 | F9: 5 | G9: 0 | H9: 0 | I9: 3 | J9: 0
A10: segunda-feira, 12 de agosto de 2024 | B10: 6 | C10: 14 | D10: 0 | E10: 0 | F10: 1 | G10: 0 | H10: 2 | I10: 11 | J10: 0
A11: terça-feira, 13 de agosto de 2024 | B11: 8 | C11: 16 | D11: 1 | E11: 1 | F11: 13 | G11: 0 | H11: 0 | I11: 1 | J11: 0
A12: quarta-feira, 14 de agosto de 2024 | B12: 12 | C12: 9 | D12: 3 | E12: 0 | F12: 5 | G12: 0 | H12: 0 | I12: 1 | J12: 0
A13: quinta-feira, 15 de agosto de 2024 | B13: 24 | C13: 19 | D13: 2 | E13: 5 | F13: 10 | G13: 0 | H13: 2 | I13: 0 | J13: 0
... A25: sexta-feira, 30 de agosto de 2024 | B25: 5 | C25: 10 | D25: 1 | E25: 1 | F25: 2 | G25: 0 | H25: 6 | I25: 0 | J25: 0
A30: Médias Diárias | B30: =AVERAGE(B2:B29) -> 9.25 | C30: =AVERAGE(C2:C29) -> 9.5 | D30: =AVERAGE(D2:D29) -> 1.4583333 | E30: =AVERAGE(E2:E29) -> 1.2083333 | F30: =AVERAGE(F2:F29) -> 3.125 | G30: =AVERAGE(G2:G29) -> 0 | H30: =AVERAGE(H2:H29) -> 2 | I30: =AVERAGE(I2:I29) -> 1.7083333 | J30: =AVERAGE(J2:J29) -> 0
A31: Somatórias | B31: =SUM(B2:B29) -> 222 | C31: =SUM(C2:C29) -> 228 | D31: =SUM(D2:D29) -> 35 | E31: =SUM(E2:E29) -> 29 | F31: =SUM(F2:F29) -> 75 | G31: =SUM(G2:G29) -> 0 | H31: =SUM(H2:H29) -> 48 | I31: =SUM(I2:I29) -> 41 | J31: =SUM(J2:J29) -> 0
A32: Porcentagem | D32: =D31/C31 -> 0.15350877 | E32: =E31/C31 -> 0.12719298 | F32: =F31/C31 -> 0.32894737 | G32: =G31/C31 -> 0 | H32: =H31/C31 -> 0.21052632 | I32: =I31/C31 -> 0.17982456 | J32: =J31/C31 -> 0

Sheet Set
A1: Data | B1: Created | C1: Resolved | D1: Everton | E1: Raphael | F1: Andre | G1: Não atribuídos | H1: Camille | I1: Jean | J1: Reynaldo
A2: segunda-feira, 2 de setembro de 2024 | B2: 5 | C2: 5 | D2: 1 | E2: 2 | G2: 0 | H2: 0 | I2: 2 | J2: 0
A3: terça-feira, 3 de setembro de 2024 | B3: 7 | C3: 2 | D3: 0 | E3: 0 | G3: 0 | H3: 0 | I3: 2 | J3: 0
A4: quarta-feira, 4 de setembro de 2024 | B4: 13 | C4: 5 | D4: 0 | E4: 1 | G4: 0 | H4: 1 | I4: 3 | J4: 0
A5: quinta-feira, 5 de setembro de 2024 | B5: 8 | C5: 11 | D5: 0 | E5: 2 | G5: 0 | H5: 1 | I5: 8 | J5: 0
A6: sexta-feira, 6 de setembro de 2024 | B6: 10 | C6: 13 | D6: 4 | E6: 3 | G6: 0 | H6: 0 | I6: 6 | J6: 0
A7: sábado, 7 de setembro de 2024 | B7: 0 | C7: 1 | D7: 1 | E7: 0 | G7: 0 | H7: 0 | I7: 0 | J7: 0
A8: segunda-feira, 9 de setembro de 2024 | B8: 10 | C8: 4 | D8: 0 | E8: 0 | G8: 0 | H8: 0 | I8: 4 | J8: 0
A9: terça-feira, 10 de setembro de 2024 | B9: 5 | C9: 7 | D9: 1 | E9: 0 | G9: 0 | H9: 4 | I9: 2 | J9: 0
A10: quarta-feira, 11 de setembro de 2024 | B10: 3 | C10: 8 | D10: 5 | E10: 0 | G10: 0 | H10: 0 | I10: 3 | J10: 0
A11: quinta-feira, 12 de setembro de 2024 | B11: 7 | C11: 11 | D11: 0 | E11: 5 | G11: 0 | H11: 0 | I11: 6 | J11: 0
A12: sexta-feira, 13 de setembro de 2024 | B12: 3 | C12: 2 | D12: 0 | E12: 1 | G12: 0 | H12: 0 | I12: 1 | J12: 0
A13: segunda-feira, 16 de setembro de 2024 | B13: 10 | C13: 7 | D13: 0 | E13: 0 | G13: 0 | H13: 0 | I13: 7 | J13: 0
A14: terça-feira, 17 de setembro de 2024 | B14: 8 | C14: 13 | D14: 2 | E14: 0 | F14: 6 | G14: 0 | H14: 4 | I14: 1 | J14: 0
A15: quarta-feira, 18 de setembro de 2024 | B15: 7 | C15: 8 | D15: 0 | E15: 0 | F15: 4 | G15: 0 | H15: 1 | I15: 3 | J15: 0
A16: quinta-feira, 19 de setembro de 2024 | B16: 7 | C16: 8 | D16: 2 | E16: 0 | F16: 3 | G16: 0 | H16: 0 | I16: 3 | J16: 0
A17: sexta-feira, 20 de setembro de 2024 | B17: 11 | C17: 6 | D17: 0 | E17: 0 | F17: 1 | G17: 0 | H17: 0 | I17: 5 | J17: 0
A18: segunda-feira, 23 de setembro de 2024 | B18: 20 | C18: 16 | D18: 0 | E18: 3 | F18: 2 | G18: 0 | H18: 1 | I18: 10 | J18: 0
A19: terça-feira, 24 de setembro de 2024 | B19: 2 | C19: 17 | D19: 2 | E19: 0 | F19: 10 | G19: 0 | H19: 4 | I19: 1 | J19: 0
A20: quarta-feira, 25 de setembro de 2024 | B20: 13 | C20: 9 | D20: 1 | E20: 1 | F20: 3 | G20: 0 | H20: 0 | I20: 4 | J20: 0
A21: quinta-feira, 26 de setembro de 2024 | B21: 11 | C21: 5 | D21: 0 | E21: 0 | F21: 1 | G21: 0 | H21: 0 | I21: 4 | J21: 0
A22: sexta-feira, 27 de setembro de 2024 | B22: 4 | C22: 9 | D22: 1 | E22: 8 | F22: 0 | G22: 0 | H22: 0 | I22: 0 | J22: 0
A23: segunda-feira, 30 de setembro de 2024 | B23: 10 | C23: 15 | D23: 1 | E23: 3 | F23: 8 | G23: 0 | H23: 0 | I23: 3 | J23: 0
A30: Médias Diárias | B30: =AVERAGE(B2:B29) -> 7.9090909 | C30: =AVERAGE(C2:C29) -> 8.2727273 | D30: =AVERAGE(D2:D29) -> 0.95454545 | E30: =AVERAGE(E2:E29) -> 1.3181818 | F30: =AVERAGE(F2:F29) -> 3.8 | G30: =AVERAGE(G2:G29) -> 0 | H30: =AVERAGE(H2:H29) -> 0.72727273 | I30: =AVERAGE(I2:I29) -> 3.5454545 | J30: =AVERAGE(J2:J29) -> 0
A31: Somatórias | B31: =SUM(B2:B29) -> 174 | C31: =SUM(C2:C29) -> 182 | D31: =SUM(D2:D29) -> 21 | E31: =SUM(E2:E29) -> 29 | F31: =SUM(F2:F29) -> 38 | G31: =SUM(G2:G29) -> 0 | H31: =SUM(H2:H29) -> 16 | I31: =SUM(I2:I29) -> 78 | J31: =SUM(J2:J29) -> 0
A32: Porcentagem | D32: =D31/C31 -> 0.11538462 | E32: =E31/C31 -> 0.15934066 | F32: =F31/C31 -> 0.20879121 | G32: =G31/C31 -> 0 | H32: =H31/C31 -> 0.087912088 | I32: =I31/C31 -> 0.42857143 | J32: =J31/C31 -> 0

Sheet Out

Sheet Nov

Sheet Dez
